Workbook
Name Aufgabe: [1]Daten!$D$3:$D$128
Name FarbeA: #REF!
Name FarbeB: #REF!
Name FarbeC: #REF!
Name FarbeD: #REF!
Name FarbeE: #REF!

Sheet Summary
C4: Week Number | D4: 2
C7: General Summary
C8: Group | D8: Total Manday | E8: Total Manday x Progress | F8: Progress | G8: Total Manday x Progress Should be | H8: Progress Should be
B9: A | C9: Rectafications | D9: =+SUMIF('E2NS Terminplan'!I:I,B9,'E2NS Terminplan'!O:O) -> 2349 | E9: =+SUMIF('E2NS Terminplan'!I:I,B9,'E2NS Terminplan'!V:V) -> 214.83536 | F9: =+E9/D9 -> 0.091458222 | G9: =+SUMIF('E2NS Terminplan'!I:I,B9,'E2NS Terminplan'!Y:Y) -> 298 | H9: =+G9/D9 -> 0.12686249
B10: B | C10: Contract | D10: =+SUMIF('E2NS Terminplan'!I:I,B10,'E2NS Terminplan'!O:O) -> 1342 | E10: =+SUMIF('E2NS Terminplan'!I:I,B10,'E2NS Terminplan'!V:V) -> 80.453425 | F10: =+E10/D10 -> 0.059950391 | G10: =+SUMIF('E2NS Terminplan'!I:I,B10,'E2NS Terminplan'!Y:Y) -> 62 | H10: =+G10/D10 -> 0.046199702
B11: C | C11: NTA | D11: =+SUMIF('E2NS Terminplan'!I:I,B11,'E2NS Terminplan'!O:O) -> 522 | E11: =+SUMIF('E2NS Terminplan'!I:I,B11,'E2NS Terminplan'!V:V) -> 65.603687 | F11: =+E11/D11 -> 0.12567756 | G11: =+SUMIF('E2NS Terminplan'!I:I,B11,'E2NS Terminplan'!Y:Y) -> 45 | H11: =+G11/D11 -> 0.086206897
D12: =SUM(D9:D11) -> 4213 | E12: =SUM(E9:E11) -> 360.89247 | F12: =+E12/D12 -> 0.085661636 | G12: =SUM(G9:G11) -> 405 | H12: =+G12/D12 -> 0.096131023
C15: Group | D15: Total Manday | E15: Total Manday x Progress | F15: Progress | G15: Total Manday x Progress Should be | H15: Progress Should be
C16: E2N | D16: =SUM(D17:D19) -> 1610 | E16: =SUM(E17:E19) -> 204.18893 | F16: =+E16/D16 -> 0.12682542 | G16: =SUM(G17:G19) -> 294 | H16: =+IFERROR(G16/D16,"") -> 0.1826087
A17: 1 | B17: A | C17: Rectafications | D17: =+SUMIFS('E2NS Terminplan'!O:O,'E2NS Terminplan'!I:I,B17,'E2NS Terminplan'!B:B,A17) -> 1222 | E17: =+SUMIFS('E2NS Terminplan'!V:V,'E2NS Terminplan'!I:I,B17,'E2NS Terminplan'!B:B,A17) -> 164.18893 | F17: =+E17/D17 -> 0.13436083 | G17: =+SUMIFS('E2NS Terminplan'!Y:Y,'E2NS Terminplan'!I:I,B17,'E2NS Terminplan'!B:B,A17) -> 262 | H17: =+IFERROR(G17/D17,"") -> 0.21440262
A18: 1 | B18: B | C18: Contract | D18: =+SUMIFS('E2NS Terminplan'!O:O,'E2NS Terminplan'!I:I,B18,'E2NS Terminplan'!B:B,A18) -> 124 | E18: =+SUMIFS('E2NS Terminplan'!V:V,'E2NS Terminplan'!I:I,B18,'E2NS Terminplan'!B:B,A18) -> 40 | F18: =+E18/D18 -> 0.32258065 | G18: =+SUMIFS('E2NS Terminplan'!Y:Y,'E2NS Terminplan'!I:I,B18,'E2NS Terminplan'!B:B,A18) -> 32 | H18: =+IFERROR(G18/D18,"") -> 0.25806452
A19: 1 | B19: C | C19: NTA | D19: =+SUMIFS('E2NS Terminplan'!O:O,'E2NS Terminplan'!I:I,B19,'E2NS Terminplan'!B:B,A19) -> 264 | E19: =+SUMIFS('E2NS Terminplan'!V:V,'E2NS Terminplan'!I:I,B19,'E2NS Terminplan'!B:B,A19) -> 0 | F19: =+E19/D19 -> 0 | G19: =+SUMIFS('E2NS Terminplan'!Y:Y,'E2NS Terminplan'!I:I,B19,'E2NS Terminplan'!B:B,A19) -> 0 | H19: =+IFERROR(G19/D19,"") -> 0
C20: E2S Exterior | D20: =SUM(D21:D23) -> 1155 | E20: =SUM(E21:E23) -> 156.70354 | F20: =+E20/D20 -> 0.13567406 | G20: =SUM(G21:G23) -> 105 | H20: =+IFERROR(G20/D20,"") -> 0.090909091
A21: 2 | B21: A | C21: Rectafications | D21: =+SUMIFS('E2NS Terminplan'!O:O,'E2NS Terminplan'!I:I,B21,'E2NS Terminplan'!B:B,A21) -> 687 | E21: =+SUMIFS('E2NS Terminplan'!V:V,'E2NS Terminplan'!I:I,B21,'E2NS Terminplan'!B:B,A21) -> 50.646429 | F21: =+E21/D21 -> 0.073721148 | G21: =+SUMIFS('E2NS Terminplan'!Y:Y,'E2NS Terminplan'!I:I,B21,'E2NS Terminplan'!B:B,A21) -> 30 | H21: =+IFERROR(G21/D21,"") -> 0.043668122
A22: 2 | B22: B | C22: Contract | D22: =+SUMIFS('E2NS Terminplan'!O:O,'E2NS Terminplan'!I:I,B22,'E2NS Terminplan'!B:B,A22) -> 336 | E22: =+SUMIFS('E2NS Terminplan'!V:V,'E2NS Terminplan'!I:I,B22,'E2NS Terminplan'!B:B,A22) -> 40.453425 | F22: =+E22/D22 -> 0.1203971 | G22: =+SUMIFS('E2NS Terminplan'!Y:Y,'E2NS Terminplan'!I:I,B22,'E2NS Terminplan'!B:B,A22) -> 30 | H22: =+IFERROR(G22/D22,"") -> 0.089285714
A23: 2 | B23: C | C23: NTA | D23: =+SUMIFS('E2NS Terminplan'!O:O,'E2NS Terminplan'!I:I,B23,'E2NS Terminplan'!B:B,A23) -> 132 | E23: =+SUMIFS('E2NS Terminplan'!V:V,'E2NS Terminplan'!I:I,B23,'E2NS Terminplan'!B:B,A23) -> 65.603687 | F23: =+E23/D23 -> 0.49699763 | G23: =+SUMIFS('E2NS Terminplan'!Y:Y,'E2NS Terminplan'!I:I,B23,'E2NS Terminplan'!B:B,A23) -> 45 | H23: =+IFERROR(G23/D23,"") -> 0.34090909
C24: E2S Courtyard | D24: =SUM(D25:D27) -> 936 | E24: =SUM(E25:E27) -> 0 | F24: =+E24/D24 -> 0 | G24: =SUM(G25:G27) -> 6 | H24: =+IFERROR(G24/D24,"") -> 0.0064102564
A25: 3 | B25: A | C25: Rectafications | D25: =+SUMIFS('E2NS Terminplan'!O:O,'E2NS Terminplan'!I:I,B25,'E2NS Terminplan'!B:B,A25) -> 120 | E25: =+SUMIFS('E2NS Terminplan'!V:V,'E2NS Terminplan'!I:I,B25,'E2NS Terminplan'!B:B,A25) -> 0 | F25: =+E25/D25 -> 0 | G25: =+SUMIFS('E2NS Terminplan'!Y:Y,'E2NS Terminplan'!I:I,B25,'E2NS Terminplan'!B:B,A25) -> 6 | H25: =+IFERROR(G25/D25,"") -> 0.05
A26: 3 | B26: B | C26: Contract | D26: =+SUMIFS('E2NS Terminplan'!O:O,'E2NS Terminplan'!I:I,B26,'E2NS Terminplan'!B:B,A26) -> 714 | E26: =+SUMIFS('E2NS Terminplan'!V:V,'E2NS Terminplan'!I:I,B26,'E2NS Terminplan'!B:B,A26) -> 0 | F26: =+E26/D26 -> 0 | G26: =+SUMIFS('E2NS Terminplan'!Y:Y,'E2NS Terminplan'!I:I,B26,'E2NS Terminplan'!B:B,A26) -> 0 | H26: =+IFERROR(G26/D26,"") -> 0
A27: 3 | B27: C | C27: NTA | D27: =+SUMIFS('E2NS Terminplan'!O:O,'E2NS Terminplan'!I:I,B27,'E2NS Terminplan'!B:B,A27) -> 102 | E27: =+SUMIFS('E2NS Terminplan'!V:V,'E2NS Terminplan'!I:I,B27,'E2NS Terminplan'!B:B,A27) -> 0 | F27: =+E27/D27 -> 0 | G27: =+SUMIFS('E2NS Terminplan'!Y:Y,'E2NS Terminplan'!I:I,B27,'E2NS Terminplan'!B:B,A27) -> 0 | H27: =+IFERROR(G27/D27,"") -> 0
C28: E2S Interior | D28: =SUM(D29:D31) -> 512 | E28: =SUM(E29:E31) -> 0 | F28: =+E28/D28 -> 0 | G28: =SUM(G29:G31) -> 0 | H28: =+IFERROR(G28/D28,"") -> 0
A29: 4 | B29: A | C29: Rectafications | D29: =+SUMIFS('E2NS Terminplan'!O:O,'E2NS Terminplan'!I:I,B29,'E2NS Terminplan'!B:B,A29) -> 320 | E29: =+SUMIFS('E2NS Terminplan'!V:V,'E2NS Terminplan'!I:I,B29,'E2NS Terminplan'!B:B,A29) -> 0 | F29: =+E29/D29 -> 0 | G29: =+SUMIFS('E2NS Terminplan'!Y:Y,'E2NS Terminplan'!I:I,B29,'E2NS Terminplan'!B:B,A29) -> 0 | H29: =+IFERROR(G29/D29,"") -> 0
A30: 4 | B30: B | C30: Contract | D30: =+SUMIFS('E2NS Terminplan'!O:O,'E2NS Terminplan'!I:I,B30,'E2NS Terminplan'!B:B,A30) -> 168 | E30: =+SUMIFS('E2NS Terminplan'!V:V,'E2NS Terminplan'!I:I,B30,'E2NS Terminplan'!B:B,A30) -> 0 | F30: =+E30/D30 -> 0 | G30: =+SUMIFS('E2NS Terminplan'!Y:Y,'E2NS Terminplan'!I:I,B30,'E2NS Terminplan'!B:B,A30) -> 0 | H30: =+IFERROR(G30/D30,"") -> 0
A31: 4 | B31: C | C31: NTA | D31: =+SUMIFS('E2NS Terminplan'!O:O,'E2NS Terminplan'!I:I,B31,'E2NS Terminplan'!B:B,A31) -> 24 | E31: =+SUMIFS('E2NS Terminplan'!V:V,'E2NS Terminplan'!I:I,B31,'E2NS Terminplan'!B:B,A31) -> 0 | F31: =+E31/D31 -> 0 | G31: =+SUMIFS('E2NS Terminplan'!Y:Y,'E2NS Terminplan'!I:I,B31,'E2NS Terminplan'!B:B,A31) -> 0 | H31: =+IFERROR(G31/D31,"") -> 0
D32: =+D28+D24+D20+D16 -> 4213 | E32: =+E28+E24+E20+E16 -> 360.89247 | F32: =+E32/D32 -> 0.085661636 | G32: =+G28+G24+G20+G16 -> 405 | H32: =+IFERROR(G32/D32,"") -> 0.096131023

Sheet E2NS Terminplan
Z4: 45931 | AA4: =TEXT(AD9,"MMMM JJ") -> November 25 | AH4: =TEXT(AM9,"MMMM JJ") -> December 25 | AO4: =TEXT(AT9,"MMMM JJ") -> December 25 | AV4: =TEXT(BA9,"MMMM JJ") -> December 25 | BC4: =TEXT(BH9,"MMMM JJ") -> December 25 | BJ4: =TEXT(BO9,"MMMM JJ") -> January 26 | BQ4: =TEXT(BV9,"MMMM JJ") -> January 26 | BX4: =TEXT(CC9,"MMMM JJ") -> January 26 | CE4: =TEXT(CJ9,"MMMM JJ") -> January 26 | CL4: =TEXT(CQ9,"MMMM JJ") -> January 26 | CS4: =TEXT(CX9,"MMMM JJ") -> February 26 | CZ4: =TEXT(DE9,"MMMM JJ") -> February 26 | DG4: =TEXT(DL9,"MMMM JJ") -> February 26 | DN4: =TEXT(DS9,"MMMM JJ") -> February 26 | DU4: =TEXT(DZ9,"MMMM JJ") -> March 26 | EB4: =TEXT(EG9,"MMMM JJ") -> March 26 | EI4: =TEXT(EN9,"MMMM JJ") -> March 26 | EP4: =TEXT(EU9,"MMMM JJ") -> March 26 | EW4: =TEXT(FB9,"MMMM JJ") -> April 26 | FD4: =TEXT(FI9,"MMMM JJ") -> April 26 | FK4: =TEXT(FP9,"MMMM JJ") -> April 26 | FR4: =TEXT(FW9,"MMMM JJ") -> April 26 | FY4: =TEXT(GD9,"MMMM JJ") -> May 26 | GF4: =TEXT(GK9,"MMMM JJ") -> May 26 | GM4: =TEXT(GR9,"MMMM JJ") -> May 26 | GT4: =TEXT(GY9,"MMMM JJ") -> May 26 | HA4: =TEXT(HF9,"MMMM JJ") -> May 26 | HH4: =TEXT(HM9,"MMMM JJ") -> June 26 | HO4: =TEXT(HT9,"MMMM JJ") -> June 26 | HV4: =TEXT(IA9,"MMMM JJ") -> June 26 | IC4: =TEXT(IH9,"MMMM JJ") -> June 26 | IJ4: =TEXT(IO9,"MMMM JJ") -> July 26 | IQ4: =TEXT(IV9,"MMMM JJ") -> July 26 | IX4: =TEXT(JC9,"MMMM JJ") -> July 26 | JE4: =TEXT(JJ9,"MMMM JJ") -> July 26 | JL4: =TEXT(JQ9,"MMMM JJ") -> August 26 | JS4: =TEXT(JX9,"MMMM JJ") -> August 26 | JZ4: =TEXT(KE9,"MMMM JJ") -> August 26 | KG4: =TEXT(KL9,"MMMM JJ") -> August 26 | KN4: =TEXT(KS9,"MMMM JJ") -> August 26 | KU4: =TEXT(KZ9,"MMMM JJ") -> September 26 | LB4: =TEXT(LG9,"MMMM JJ") -> September 26 | LI4: =TEXT(LN9,"MMMM JJ") -> September 26 | LP4: =TEXT(LU9,"MMMM JJ") -> September 26 | LW4: =TEXT(MB9,"MMMM JJ") -> October 26 | MD4: =TEXT(MI9,"MMMM JJ") -> October 26 | MK4: =TEXT(MP9,"MMMM JJ") -> October 26 | MR4: =TEXT(MW9,"MMMM JJ") -> October 26 | MY4: =TEXT(ND9,"MMMM JJ") -> October 26 | NF4: =TEXT(NK9,"MMMM JJ") -> November 26 | NM4: =TEXT(NR9,"MMMM JJ") -> November 26 | NT4: =TEXT(NY9,"MMMM JJ") -> November 26
R5: E2NS | AA5: =WEEKNUM(AF9,21) -> 48 | AH5: =WEEKNUM(AM9,21) -> 49 | AO5: =WEEKNUM(AT9,21) -> 50 | AV5: =WEEKNUM(BA9,21) -> 51 | BC5: =WEEKNUM(BH9,21) -> 52 | BJ5: =WEEKNUM(BO9,21) -> 1 | BQ5: =WEEKNUM(BV9,21) -> 2 | BX5: =WEEKNUM(CC9,21) -> 3 | CE5: =WEEKNUM(CJ9,21) -> 4 | CL5: =WEEKNUM(CQ9,21) -> 5 | CS5: =WEEKNUM(CX9,21) -> 6 | CZ5: =WEEKNUM(DE9,21) -> 7 | DG5: =WEEKNUM(DL9,21) -> 8 | DN5: =WEEKNUM(DS9,21) -> 9 | DU5: =WEEKNUM(DZ9,21) -> 10 | EB5: =WEEKNUM(EG9,21) -> 11 | EI5: =WEEKNUM(EN9,21) -> 12 | EP5: =WEEKNUM(EU9,21) -> 13 | EW5: =WEEKNUM(FB9,21) -> 14 | FD5: =WEEKNUM(FI9,21) -> 15 | FK5: =WEEKNUM(FP9,21) -> 16 | FR5: =WEEKNUM(FW9,21) -> 17 | FY5: =WEEKNUM(GD9,21) -> 18 | GF5: =WEEKNUM(GK9,21) -> 19 | GM5: =WEEKNUM(GR9,21) -> 20 | GT5: =WEEKNUM(GY9,21) -> 21 | HA5: =WEEKNUM(HF9,21) -> 22 | HH5: =WEEKNUM(HM9,21) -> 23 | HO5: =WEEKNUM(HT9,21) -> 24 | HV5: =WEEKNUM(IA9,21) -> 25 | IC5: =WEEKNUM(IH9,21) -> 26 | IJ5: =WEEKNUM(IO9,21) -> 27 | IQ5: =WEEKNUM(IV9,21) -> 28 | IX5: =WEEKNUM(JC9,21) -> 29 | JE5: =WEEKNUM(JJ9,21) -> 30 | JL5: =WEEKNUM(JQ9,21) -> 31 | JS5: =WEEKNUM(JX9,21) -> 32 | JZ5: =WEEKNUM(KE9,21) -> 33 | KG5: =WEEKNUM(KL9,21) -> 34 | KN5: =WEEKNUM(KS9,21) -> 35 | KU5: =WEEKNUM(KZ9,21) -> 36 | LB5: =WEEKNUM(LG9,21) -> 37 | LI5: =WEEKNUM(LN9,21) -> 38 | LP5: =WEEKNUM(LU9,21) -> 39 | LW5: =WEEKNUM(MB9,21) -> 40 | MD5: =WEEKNUM(MI9,21) -> 41 | MK5: =WEEKNUM(MP9,21) -> 42 | MR5: =WEEKNUM(MW9,21) -> 43 | MY5: =WEEKNUM(ND9,21) -> 44 | NF5: =WEEKNUM(NK9,21) -> 45 | NM5: =WEEKNUM(NR9,21) -> 46 | NT5: =WEEKNUM(NY9,21) -> 47
AA6: 41 | AB6: 42 | AC6: 43 | AD6: 44 | AE6: 45 | AF6: 46 | AG6: 47 | AH6: 48 | AI6: 49 | AJ6: 50 | AK6: 51 | AL6: 52 | AM6: 53 | AN6: 54 | AO6: 55 | AP6: 56 | AQ6: 57 | AR6: 58 | AS6: 59 | AT6: 60 | AU6: 61 | AV6: 62 | AW6: 63 | AX6: 64 | AY6: 65 | AZ6: 66 | BA6: 67 | BB6: 68 | BC6: 69 | BD6: 70 | BE6: 71 | BF6: 72 | BG6: 73 | BH6: 74 | BI6: 75 | BJ6: 76 | BK6: 77 | BL6: 78 | BM6: 79 | BN6: 80 | BO6: 81 | BP6: 82 | BQ6: 83 | BR6: 84 | BS6: 85 | BT6: 86 | BU6: 87 | BV6: 88 | BW6: 89 | BX6: 90 | BY6: 91 | BZ6: 92 | CA6: 93 | CB6: 94 | CC6: 95 | CD6: 96 | CE6: 97 | CF6: 98 | CG6: 99 | CH6: 100 | CI6: 101 | CJ6: 102 | CK6: 103 | CL6: 104 | CM6: 105 | CN6: 106 | CO6: 107 | CP6: 108 | CQ6: 109 | CR6: 110 | CS6: 111 | CT6: 112 | CU6: 113 | CV6: 114 | CW6: 115 | CX6: 116 | CY6: 117 | CZ6: 118 | DA6: 119 | DB6: 120 | DC6: 121 | DD6: 122 | DE6: 123 | DF6: 124 | DG6: 125 | DH6: 126 | DI6: 127 | DJ6: 128 | DK6: 129 | DL6: 130 | DM6: 131 | DN6: 132 | DO6: 133 | DP6: 134 | DQ6: 135 | DR6: 136 | DS6: 137 | DT6: 138 | DU6: 139 | DV6: 140 | DW6: 141 | DX6: 142 | DY6: 143 | DZ6: 144 | EA6: 145 | EB6: 146 | EC6: 147 | ED6: 148 | EE6: 149 | EG6: 151 | EH6: 152 | EI6: 153 | EJ6: 154 | EK6: 155 | EL6: 156 | EM6: 157 | EN6: 158 | EO6: 159 | EP6: 160 | EQ6: 161 | ER6: 162 | ES6: 163 | ET6: 164 | EU6: 165 | EV6: 166 | EW6: 167 | EX6: 168 | EY6: 169 | EZ6: 170 | FA6: 171 | FB6: 172 | FC6: 173 | FD6: 174 | FE6: 175 | FF6: 176 | FG6: 177 | FH6: 178 | FI6: 179 | FJ6: 180 | FK6: 181 | FL6: 182 | FM6: 183 | FN6: 184 | FO6: 185 | FP6: 186 | FQ6: 187 | FR6: 188 | FS6: 189 | FT6: 190 | FU6: 191 | FV6: 192 | FW6: 193 | FX6: 194 | FY6: 195 | FZ6: 196 | GA6: 197 | GB6: 198 | GC6: 199 | GD6: 200 | GE6: 201 | GF6: 202 | GG6: 203 | GH6: 204 | GI6: 205 | GJ6: 206 | GK6: 207 | GL6: 208 | GM6: 209 | GN6: 210 | GO6: 211 | GP6: 212 | GQ6: 213 | GR6: 214 | GS6: 215 | GT6: 216 | GU6: 217 | GV6: 218 | GW6: 219 | GX6: 220 | GY6: 221 | GZ6: 222 | HA6: 223 | HB6: 224 | HC6: 225 | HD6: 226 | HE6: 227 | HF6: 228 | HG6: 229 | HH6: 230 | HI6: 231 | HJ6: 232 | HK6: 233 | HL6: 234 | HM6: 235 | HN6: 236 | HO6: 237 | HP6: 238 | HQ6: 239 | HR6: 240 | HS6: 241 | HT6: 242 | HU6: 243 | HV6: 244 | HW6: 245 | HX6: 246 | HY6: 247 | HZ6: 248 | IA6: 249 | IB6: 250 | IC6: 251 | ID6: 252 | IE6: 253 | IF6: 254 | IG6: 255 | IH6: 256 | II6: 257 | IJ6: 258 | IK6: 259 | IL6: 260 | IM6: 261 | IN6: 262 | IO6: 263 | IP6: 264 | IQ6: 265 | IR6: 266 | IS6: 267 | IT6: 268 | IU6: 269 | IV6: 270 | IW6: 271 | IX6: 272 | IY6: 273 | IZ6: 274 | JA6: 275 | JB6: 276 | JC6: 277 | JD6: 278 | JE6: 279 | JF6: 280 | JG6: 281 | JH6: 282 | JI6: 283 | JJ6: 284 | JK6: 285 | JL6: 286 | JM6: 287 | JN6: 288 | JO6: 289 | JP6: 290 | JQ6: 291 | JR6: 292 | JS6: 293 | JT6: 294 | JU6: 295 | JV6: 296 | JW6: 297 | JX6: 298 | JY6: 299 | JZ6: 300 | KA6: 301 | KB6: 302 | KC6: 303 | KD6: 304 | KE6: 305 | KF6: 306 | KG6: 307 | KH6: 308 | KI6: 309 | KJ6: 310 | KK6: 311 | KL6: 312 | KM6: 313 | KN6: 314 | KO6: 315 | KP6: 316 | KQ6: 317 | KR6: 318 | KS6: 319 | KT6: 320 | KU6: 321 | KV6: 322 | KW6: 323 | KX6: 324 | KY6: 325 | KZ6: 326 | LA6: 327 | LB6: 328 | LC6: 329 | LD6: 330 | LE6: 331 | LF6: 332 | LG6: 333 | LH6: 334 | LI6: 335 | LJ6: 336 | LK6: 337 | LL6: 338 | LM6: 339 | LN6: 340 | LO6: 341 | LP6: 342 | LQ6: 343 | LR6: 344 | LS6: 345 | LT6: 346 | LU6: 347 | LV6: 348 | LW6: 349 | LX6: 350 | LY6: 351 | LZ6: 352 | MA6: 353 | MB6: 354 | MC6: 355 | MD6: 356 | ME6: 357 | MF6: 358 | MG6: 359 | MH6: 360 | MI6: 361 | MJ6: 362 | MK6: 363 | ML6: 364 | MM6: 365 | MN6: 366 | MO6: 367 | MP6: 368 | MQ6: 369 | MR6: 370 | MS6: 371 | MT6: 372 | MU6: 373 | MV6: 374 | MW6: 375 | MX6: 376 | MY6: 377 | MZ6: 378 | NA6: 379 | NB6: 380 | NC6: 381 | ND6: 382 | NE6: 383 | NF6: 384 | NG6: 385 | NH6: 386 | NI6: 387 | NJ6: 388 | NK6: 389 | NL6: 390 | NM6: 391 | NN6: 392 | NO6: 393 | NP6: 394 | NQ6: 395 | NR6: 396 | NS6: 397 | NT6: 398 | NU6: 399 | NV6: 400 | NW6: 401 | NX6: 402 | NY6: 403 | NZ6: 404
AA7: =TEXT(AA9,"TTT") -> Mon | AB7: =TEXT(AB9,"TTT") -> Tue | AC7: =TEXT(AC9,"TTT") -> Wed | AD7: =TEXT(AD9,"TTT") -> Thu | AE7: =TEXT(AE9,"TTT") -> Fri | AF7: =TEXT(AF9,"TTT") -> Sat | AG7: =TEXT(AG9,"TTT") -> Sun | AH7: =TEXT(AH9,"TTT") -> Mon | ... NZ7: =TEXT(NZ9,"TTT") -> Sun
AA8: =+_xlfn.ISOWEEKNUM(AA9) -> 48 | AB8: =+_xlfn.ISOWEEKNUM(AB9) -> 48 | AC8: =+_xlfn.ISOWEEKNUM(AC9) -> 48 | AD8: =+_xlfn.ISOWEEKNUM(AD9) -> 48 | AE8: =+_xlfn.ISOWEEKNUM(AE9) -> 48 | AF8: =+_xlfn.ISOWEEKNUM(AF9) -> 48 | AG8: =+_xlfn.ISOWEEKNUM(AG9) -> 48 | AH8: =+_xlfn.ISOWEEKNUM(AH9) -> 49 | ... NZ8: =+_xlfn.ISOWEEKNUM(NZ9) -> 47
Z9: x | AA9: 45985 | AB9: =AA9+1 -> 45986 | AC9: =AB9+1 -> 45987 | AD9: =AC9+1 -> 45988 | AE9: =AD9+1 -> 45989 | AF9: =AE9+1 -> 45990 | AG9: =AF9+1 -> 45991 | AH9: =AG9+1 -> 45992 | AI9: =AH9+1 -> 45993 | ... NZ9: =NY9+1 -> 46348
E10: Pos. | F10: Aufgabe/Tätigkeit | G10: Presequities | H10: Responsible | I10: Group | J10: QTY | K10: Done | L10: Rem. | M10: Manpower | N10: Duration | O10: Total Manday | R10: Beginn [Datum] | S10: =IF($Z$9="x","Ende nach [AT]","Endet nach [Tagen]") -> Ende nach [AT] | T10: Ende [Datum] | U10: Status | W10: =+"KW"&W12&" Progress" -> KW2 Progress | X10: =+"Cumulative Progress =<"&"KW"&W12 -> Cumulative Progress =<KW2 | Z10: Anmerkungen | AG10: µ | AL10: µ | AM10: µ | AN10: µ | AU10: µ | AZ10: µ | BA10: µ | BB10: µ
O11: =+O12+O45+O89+O125 -> 4169 | U11: =+(O12*U12+O45*U45+O89*U89+O125*U125)/O11 -> 0.088484642 | W11: =HLOOKUP(W12,AA8:PLB9,2,FALSE)+6 -> 46033 | AA11: =SUM(AA13:AA180) -> 15 | AB11: =SUM(AB13:AB180) -> 15 | AC11: =SUM(AC13:AC180) -> 15 | AD11: =SUM(AD13:AD180) -> 15 | AE11: =SUM(AE13:AE180) -> 15 | AF11: =SUM(AF13:AF180) -> 15 | AG11: =SUM(AG13:AG180) -> 0 | AH11: =SUM(AH13:AH180) -> 19 | ... HG11: =SUM(HG13:HG180) -> 0
B12: 1 | C12: 0 | D12: 0 | E12: =B12&"."&C12&"."&D12 -> 1.0.0 | F12: E2 N | O12: =+SUM(O13,O18,O22,O23,O26:O33,O36) -> 1610 | T12: =+MAX(T13:T44) -> 46115 | U12: =+SUM(O13*U13,O18*U18,O22*U22,O23*U23,SUMPRODUCT(O26:O33,U26:U33),O36*U36)/O12 -> 0.12682542 | V12: =+U12*O12 -> 204.18893 | W12: =+Summary!D4 -> 2 | Y12: =+SUM(Y13,Y18,Y22,Y23,Y26:Y33,Y36) -> 48
B13: =+B12 -> 1 | C13: 1 | D13: 0 | E13: =B13&"."&C13&"."&D13 -> 1.1.0 | F13: E2N Outside Windows | O13: =SUM(O14:O17) -> 540 | T13: =IF(S13<>"",IF(#REF!="x",WORKDAY(IF(WEEKDAY(R13,1)=7,R13+2,IF(WEEKDAY(R13,1)=1,R13+1,R13)),S13-1),R13+S13-1),"") | U13: =+SUMPRODUCT(U14:U17,O14:O17)/O13 -> 0.02374169 | V13: =+U13*O13 -> 12.820513 | Y13: =+X13*O13 -> 0
B14: =+B13 -> 1 | C14: 1 | D14: 1 | E14: =B14&"."&C14&"."&D14 -> 1.1.1 | F14: Dismantling of Drywall + Al Sheet | G14: 1 | H14: MYA | I14: A | J14: 156 | K14: 8 | L14: =+J14-K14 -> 148 | M14: 2 | N14: 125 | O14: =+N14*M14 -> 250 | P14: =+SUM(AA14:NZ14) -> 250 | Q14: =+O14-P14 -> 0 | R14: 45999 | S14: 40 | T14: =IF(S14<>"",IF($Z$9="x",WORKDAY(IF(WEEKDAY(R14,1)=7,R14+2,IF(WEEKDAY(R14,1)=1,R14+1,R14)),S14-1),R14+S14-1),"") -> 46052 | U14: =+K14/J14 -> 0.051282051 | V14: =+U14*O14 -> 12.820513 | W14: =SUMIFS($AA14:$NZ14, $AA$8:$NZ$8, $W$12)/$O14 -> 0 | X14: =SUMIF($AA$9:$NZ$9, "<=" & $W$11,$AA14:$NZ14)/$O14 -> 0.408 | Y14: =+X14*O14 -> 102 | AB14: 2 | AO14: 10 | AP14: 10 | AQ14: 10 | AR14: 10 | AS14: 10 | AT14: 10 | AV14: 8 | AW14: 8 | AX14: 8 | AY14: 8 | AZ14: 8 | BX14: 10 | BY14: 10 | BZ14: 10 | CA14: 10 | CB14: 10 | CC14: 10 | CE14: 8 | CF14: 8 | CG14: 8 | CH14: 8 | CI14: 8 | CJ14: 8 | CL14: 8 | CM14: 8 | CN14: 6 | CO14: 6 | CP14: 6 | CQ14: 6
B15: =+B14 -> 1 | C15: 1 | D15: 2 | E15: =B15&"."&C15&"."&D15 -> 1.1.2 | F15: Application of New Membrane | G15: 1 | H15: MYA | I15: A | J15: =+J14 -> 156 | K15: 0 | L15: =+J15-K15 -> 156 | M15: 2 | N15: 80 | O15: =+N15*M15 -> 160 | P15: =+SUM(AA15:NZ15) -> 164 | Q15: =+O15-P15 -> -4 | R15: 46006 | S15: 45 | T15: =IF(S15<>"",IF($Z$9="x",WORKDAY(IF(WEEKDAY(R15,1)=7,R15+2,IF(WEEKDAY(R15,1)=1,R15+1,R15)),S15-1),R15+S15-1),"") -> 46066 | U15: =+K15/J15 -> 0 | V15: =+U15*O15 -> 0 | W15: =SUMIFS($AA15:$NZ15, $AA$8:$NZ$8, $W$12)/$O15 -> 0 | X15: =SUMIF($AA$9:$NZ$9, "<=" & $W$11,$AA15:$NZ15)/$O15 -> 0.075 | Y15: =+X15*O15 -> 12 | AV15: 2 | AW15: 2 | AX15: 2 | AY15: 2 | AZ15: 4 | BX15: 8 | BY15: 8 | BZ15: 8 | CA15: 8 | CB15: 8 | CC15: 8 | CE15: 6 | CF15: 6 | CG15: 6 | CH15: 6 | CI15: 6 | CJ15: 6 | CL15: 4 | CM15: 4 | CN15: 6 | CO15: 6 | CP15: 6 | CQ15: 6 | CS15: 4 | CT15: 4 | CU15: 4 | CV15: 4 | CW15: 4 | CX15: 4 | CZ15: 2 | DA15: 2 | DB15: 2 | DC15: 2 | DD15: 2 | DE15: 2
B16: =+B15 -> 1 | C16: 1 | D16: =+D15+1 -> 3 | E16: =B16&"."&C16&"."&D16 -> 1.1.3 | F16: Installation of Al. Sheet | G16: 1 | H16: MYA | I16: A | J16: =+J15 -> 156 | K16: 0 | L16: =+J16-K16 -> 156 | M16: 2 | N16: 65 | O16: =+N16*M16 -> 130 | P16: =+SUM(AA16:NZ16) -> 132 | Q16: =+O16-P16 -> -2 | R16: 46041 | S16: 20 | T16: =IF(S16<>"",IF($Z$9="x",WORKDAY(IF(WEEKDAY(R16,1)=7,R16+2,IF(WEEKDAY(R16,1)=1,R16+1,R16)),S16-1),R16+S16-1),"") -> 46066 | U16: =+K16/J16 -> 0 | V16: =+U16*O16 -> 0 | W16: =SUMIFS($AA16:$NZ16, $AA$8:$NZ$8, $W$12)/$O16 -> 0 | X16: =SUMIF($AA$9:$NZ$9, "<=" & $W$11,$AA16:$NZ16)/$O16 -> 0 | Y16: =+X16*O16 -> 0 | CE16: 4 | CF16: 4 | CG16: 4 | CH16: 4 | CI16: 4 | CJ16: 4 | CL16: 4 | CM16: 4 | CN16: 4 | CO16: 4 | CP16: 4 | CQ16: 4 | CS16: 6 | CT16: 6 | CU16: 6 | CV16: 6 | CW16: 6 | CX16: 6 | CZ16: 8 | DA16: 8 | DB16: 8 | DC16: 8 | DD16: 8 | DE16: 8
B17: =+B15 -> 1 | C17: 1 | D17: =+D16+1 -> 4 | E17: =B17&"."&C17&"."&D17 -> 1.1.4 | F17: Installation of New Drywall | G17: 1 | H17: XXX | I17: A | J17: =+J15 -> 156 | K17: 0 | L17: =+J17-K17 -> 156 | O17: =+N17*M17 -> 0 | P17: =+SUM(AA17:NZ17) -> 0 | Q17: =+O17-P17 -> 0 | T17: =IF(S17<>"",IF($Z$9="x",WORKDAY(IF(WEEKDAY(R17,1)=7,R17+2,IF(WEEKDAY(R17,1)=1,R17+1,R17)),S17-1),R17+S17-1),"") | U17: =+K17/J17 -> 0 | V17: =+U17*O17 -> 0 | Y17: =+X17*O17 -> 0
B18: =+B17 -> 1 | C18: =+C17+1 -> 2 | D18: 0 | E18: =B18&"."&C18&"."&D18 -> 1.2.0 | F18: E2N Courtyard Windows | O18: =SUM(O19:O21) -> 160 | T18: =IF(S18<>"",IF($Z$9="x",WORKDAY(IF(WEEKDAY(R18,1)=7,R18+2,IF(WEEKDAY(R18,1)=1,R18+1,R18)),S18-1),R18+S18-1),"") | U18: =+SUMPRODUCT(U19:U21,O19:O21)/O18 -> 0.79605263 | V18: =+U18*O18 -> 127.36842 | Y18: =+X18*O18 -> 0
B19: =+B18 -> 1 | C19: =+C18 -> 2 | D19: =+D18+1 -> 1 | E19: =B19&"."&C19&"."&D19 -> 1.2.1 | F19: Dismantling of Drywall | G19: 1 | H19: MYA | I19: A | J19: 76 | K19: 76 | L19: =+J19-K19 -> 0 | M19: 10 | N19: 8 | O19: =+N19*M19 -> 80 | P19: =+SUM(AA19:NZ19) -> 80 | Q19: =+O19-P19 -> 0 | R19: 45985 | S19: 20 | T19: =IF(S19<>"",IF($Z$9="x",WORKDAY(IF(WEEKDAY(R19,1)=7,R19+2,IF(WEEKDAY(R19,1)=1,R19+1,R19)),S19-1),R19+S19-1),"") -> 46010 | U19: =+K19/J19 -> 1 | V19: =+U19*O19 -> 80 | W19: =SUMIFS($AA19:$NZ19, $AA$8:$NZ$8, $W$12)/$O19 -> 0 | X19: =SUMIF($AA$9:$NZ$9, "<=" & $W$11,$AA19:$NZ19)/$O19 -> 1 | Y19: =+X19*O19 -> 80 | AA19: 2 | AB19: 3 | AC19: 3 | AD19: 2 | AE19: 2 | AF19: 2 | AH19: 4 | AI19: 4 | AJ19: 4 | AK19: 4 | AL19: 4 | AM19: 4 | AO19: 4 | AP19: 4 | AQ19: 4 | AR19: 4 | AS19: 4 | AT19: 4 | AV19: 4 | AW19: 4 | AX19: 4 | AY19: 4 | AZ19: 2
B20: =+B19 -> 1 | C20: =+C19 -> 2 | D20: =+D19+1 -> 2 | E20: =B20&"."&C20&"."&D20 -> 1.2.2 | F20: Application of New Membrane | G20: 1 | H20: MYA | I20: A | J20: =+J19 -> 76 | K20: 45 | L20: =+J20-K20 -> 31 | M20: 10 | N20: 8 | O20: =+N20*M20 -> 80 | P20: =+SUM(AA20:NZ20) -> 44 | Q20: =+O20-P20 -> 36 | R20: 45999 | S20: 10 | T20: =IF(S20<>"",IF($Z$9="x",WORKDAY(IF(WEEKDAY(R20,1)=7,R20+2,IF(WEEKDAY(R20,1)=1,R20+1,R20)),S20-1),R20+S20-1),"") -> 46010 | U20: =+K20/J20 -> 0.59210526 | V20: =+U20*O20 -> 47.368421 | W20: =SUMIFS($AA20:$NZ20, $AA$8:$NZ$8, $W$12)/$O20 -> 0 | X20: =SUMIF($AA$9:$NZ$9, "<=" & $W$11,$AA20:$NZ20)/$O20 -> 0.55 | Y20: =+X20*O20 -> 44 | AO20: 4 | AP20: 4 | AQ20: 4 | AR20: 4 | AS20: 4 | AT20: 4 | AV20: 4 | AW20: 4 | AX20: 4 | AY20: 4 | AZ20: 4
B21: =+B20 -> 1 | C21: =+C20 -> 2 | D21: =+D20+1 -> 3 | E21: =B21&"."&C21&"."&D21 -> 1.2.3 | F21: Installation of New Drywall | G21: 1 | H21: XXX | I21: A | J21: =+J20 -> 76 | K21: 0 | L21: =+J21-K21 -> 76 | O21: =+N21*M21 -> 0 | P21: =+SUM(AA21:NZ21) -> 0 | Q21: =+O21-P21 -> 0 | T21: =IF(S21<>"",IF($Z$9="x",WORKDAY(IF(WEEKDAY(R21,1)=7,R21+2,IF(WEEKDAY(R21,1)=1,R21+1,R21)),S21-1),R21+S21-1),"") | U21: =+K21/J21 -> 0 | V21: =+U21*O21 -> 0 | Y21: =+X21*O21 -> 0
B22: =+B21 -> 1 | C22: =+C19+1 -> 3 | D22: 0 | E22: =B22&"."&C22&"."&D22 -> 1.3.0 | F22: Garage entrance aluminum cladding (north) | H22: MYA | I22: B | J22: 1 | K22: 1 | L22: =+J22-K22 -> 0 | M22: 4 | N22: 6 | O22: =+N22*M22 -> 24 | R22: 45992 | S22: 5 | T22: =IF(S22<>"",IF($Z$9="x",WORKDAY(IF(WEEKDAY(R22,1)=7,R22+2,IF(WEEKDAY(R22,1)=1,R22+1,R22)),S22-1),R22+S22-1),"") -> 45996 | U22: =+K22/J22 -> 1 | V22: =+U22*O22 -> 24 | W22: =SUMIFS($AA22:$NZ22, $AA$8:$NZ$8, $W$12)/$O22 -> 0 | X22: =SUMIF($AA$9:$NZ$9, "<=" & $W$11,$AA22:$NZ22)/$O22 -> 1 | Y22: =+X22*O22 -> 24 | AH22: 4 | AI22: 4 | AJ22: 4 | AK22: 4 | AL22: 4 | AM22: 4
B23: =+B22 -> 1 | C23: =+C22+1 -> 4 | D23: 0 | E23: =B23&"."&C23&"."&D23 -> 1.4.0 | F23: Hörmann Door (West) | O23: =SUM(O24:O25) -> 24 | T23: =IF(S23<>"",IF($Z$9="x",WORKDAY(IF(WEEKDAY(R23,1)=7,R23+2,IF(WEEKDAY(R23,1)=1,R23+1,R23)),S23-1),R23+S23-1),"") | U23: =+SUMPRODUCT(U24:U25,O24:O25)/O23 -> 0.66666667 | V23: =+U23*O23 -> 16 | W23: =SUMIFS($AA23:$NZ23, $AA$8:$NZ$8, $W$12)/$O23 -> 0 | X23: =SUMIF($AA$9:$NZ$9, "<=" & $W$11,$AA23:$NZ23)/$O23 -> 0 | Y23: =+X23*O23 -> 0
B24: =+B23 -> 1 | C24: =+C23 -> 4 | D24: 1 | E24: =B24&"."&C24&"."&D24 -> 1.4.1 | F24: Steel structure | G24: 2 | H24: MYA | I24: B | J24: 1 | K24: 1 | L24: =+J24-K24 -> 0 | M24: 4 | N24: 4 | O24: =+N24*M24 -> 16 | P24: =+SUM(AA24:NZ24) -> 0 | Q24: =+O24-P24 -> 16 | T24: =IF(S24<>"",IF($Z$9="x",WORKDAY(IF(WEEKDAY(R24,1)=7,R24+2,IF(WEEKDAY(R24,1)=1,R24+1,R24)),S24-1),R24+S24-1),"") | U24: =+K24/J24 -> 1 | V24: =+U24*O24 -> 16 | W24: =SUMIFS($AA24:$NZ24, $AA$8:$NZ$8, $W$12)/$O24 -> 0 | X24: =SUMIF($AA$9:$NZ$9, "<=" & $W$11,$AA24:$NZ24)/$O24 -> 0 | Y24: =+X24*O24 -> 0
B25: =+B24 -> 1 | C25: =+C24 -> 4 | D25: 2 | E25: =B25&"."&C25&"."&D25 -> 1.4.2 | F25: Door | G25: 2 | H25: MYA | I25: B | J25: 1 | K25: 0 | L25: =+J25-K25 -> 1 | M25: 4 | N25: 2 | O25: =+N25*M25 -> 8 | P25: =+SUM(AA25:NZ25) -> 8 | Q25: =+O25-P25 -> 0 | R25: 46002 | S25: 2 | T25: =IF(S25<>"",IF($Z$9="x",WORKDAY(IF(WEEKDAY(R25,1)=7,R25+2,IF(WEEKDAY(R25,1)=1,R25+1,R25)),S25-1),R25+S25-1),"") -> 46003 | U25: =+K25/J25 -> 0 | V25: =+U25*O25 -> 0 | W25: =SUMIFS($AA25:$NZ25, $AA$8:$NZ$8, $W$12)/$O25 -> 0 | X25: =SUMIF($AA$9:$NZ$9, "<=" & $W$11,$AA25:$NZ25)/$O25 -> 1 | Y25: =+X25*O25 -> 8 | AR25: 4 | AS25: 4
B26: =+B25 -> 1 | C26: =+C25+1 -> 5 | D26: 0 | E26: =B26&"."&C26&"."&D26 -> 1.5.0 | F26: FT-07 Glass Rotation and Gasket replacement (East-West) | G26: 2,3,4 | H26: MYA | I26: A | J26: 7 | K26: 0 | L26: =+J26-K26 -> 7 | M26: 3 | N26: 6 | O26: =+N26*M26 -> 18 | P26: =+SUM(AA26:NZ26) -> 18 | Q26: =+O26-P26 -> 0 | R26: 46041 | S26: 5 | T26: =IF(S26<>"",IF($Z$9="x",WORKDAY(IF(WEEKDAY(R26,1)=7,R26+2,IF(WEEKDAY(R26,1)=1,R26+1,R26)),S26-1),R26+S26-1),"") -> 46045 | U26: =+K26/J26 -> 0 | V26: =+U26*O26 -> 0 | W26: =SUMIFS($AA26:$NZ26, $AA$8:$NZ$8, $W$12)/$O26 -> 0 | X26: =SUMIF($AA$9:$NZ$9, "<=" & $W$11,$AA26:$NZ26)/$O26 -> 0 | Y26: =+X26*O26 -> 0 | CE26: 3 | CF26: 3 | CG26: 3 | CH26: 3 | CI26: 3 | CJ26: 3
B27: =+B26 -> 1 | C27: =+C26+1 -> 6 | D27: 0 | E27: =B27&"."&C27&"."&D27 -> 1.6.0 | F27: Breuninger facade –Bottom Al. Finishing Reinforcement | G27: 2 | H27: MYA | I27: A | J27: 30 | K27: 30 | L27: =+J27-K27 -> 0 | M27: 2 | N27: 6 | O27: =+N27*M27 -> 12 | P27: =+SUM(AA27:NZ27) -> 12 | Q27: =+O27-P27 -> 0 | R27: 45992 | S27: 5 | T27: =IF(S27<>"",IF($Z$9="x",WORKDAY(IF(WEEKDAY(R27,1)=7,R27+2,IF(WEEKDAY(R27,1)=1,R27+1,R27)),S27-1),R27+S27-1),"") -> 45996 | U27: =+K27/J27 -> 1 | V27: =+U27*O27 -> 12 | W27: =SUMIFS($AA27:$NZ27, $AA$8:$NZ$8, $W$12)/$O27 -> 0 | X27: =SUMIF($AA$9:$NZ$9, "<=" & $W$11,$AA27:$NZ27)/$O27 -> 1 | Y27: =+X27*O27 -> 12 | AH27: 2 | AI27: 2 | AJ27: 2 | AK27: 2 | AL27: 2 | AM27: 2
B28: =+B27 -> 1 | C28: =+C27+1 -> 7 | D28: 0 | E28: =B28&"."&C28&"."&D28 -> 1.7.0 | F28: RT02 Additional Balustrade Module (NTA) | G28: 2 | H28: MYA | I28: C | J28: 2 | K28: 0 | L28: =+J28-K28 -> 2 | M28: 4 | N28: 3 | O28: =+N28*M28 -> 12 | P28: =+SUM(AA28:NZ28) -> 12 | Q28: =+O28-P28 -> 0 | R28: 46048 | S28: 3 | T28: =IF(S28<>"",IF($Z$9="x",WORKDAY(IF(WEEKDAY(R28,1)=7,R28+2,IF(WEEKDAY(R28,1)=1,R28+1,R28)),S28-1),R28+S28-1),"") -> 46050 | U28: =+K28/J28 -> 0 | V28: =+U28*O28 -> 0 | W28: =SUMIFS($AA28:$NZ28, $AA$8:$NZ$8, $W$12)/$O28 -> 0 | X28: =SUMIF($AA$9:$NZ$9, "<=" & $W$11,$AA28:$NZ28)/$O28 -> 0 | Y28: =+X28*O28 -> 0 | CL28: 4 | CM28: 4 | CN28: 4
B29: =+B28 -> 1 | C29: =+C28+1 -> 8 | D29: 0 | E29: =B29&"."&C29&"."&D29 -> 1.8.0 | F29: FT-13 Canopy – Anodized Al. Sheet Replacement + Cap Replacement | G29: 2.3 | H29: MYA | I29: B | J29: 60 | K29: 0 | L29: =+J29-K29 -> 60 | M29: 4 | N29: 6 | O29: =+N29*M29 -> 24 | P29: =+SUM(AA29:NZ29) -> 0 | Q29: =+O29-P29 -> 24 | T29: =IF(S29<>"",IF($Z$9="x",WORKDAY(IF(WEEKDAY(R29,1)=7,R29+2,IF(WEEKDAY(R29,1)=1,R29+1,R29)),S29-1),R29+S29-1),"") | U29: =+K29/J29 -> 0 | V29: =+U29*O29 -> 0 | W29: =SUMIFS($AA29:$NZ29, $AA$8:$NZ$8, $W$12)/$O29 -> 0 | X29: =SUMIF($AA$9:$NZ$9, "<=" & $W$11,$AA29:$NZ29)/$O29 -> 0 | Y29: =+X29*O29 -> 0
B30: =+B29 -> 1 | C30: =+C29+1 -> 9 | D30: 0 | E30: =B30&"."&C30&"."&D30 -> 1.9.0 | F30: E2N - E3 Attika Connection Detail (East+North) | G30: 2 | H30: MYA | I30: B | J30: 2 | K30: 0 | L30: =+J30-K30 -> 2 | M30: 2 | N30: 4 | O30: =+N30*M30 -> 8 | P30: =+SUM(AA30:NZ30) -> 12 | Q30: =+O30-P30 -> -4 | R30: 46051 | S30: 2 | T30: =IF(S30<>"",IF($Z$9="x",WORKDAY(IF(WEEKDAY(R30,1)=7,R30+2,IF(WEEKDAY(R30,1)=1,R30+1,R30)),S30-1),R30+S30-1),"") -> 46052 | U30: =+K30/J30 -> 0 | V30: =+U30*O30 -> 0 | W30: =SUMIFS($AA30:$NZ30, $AA$8:$NZ$8, $W$12)/$O30 -> 0 | X30: =SUMIF($AA$9:$NZ$9, "<=" & $W$11,$AA30:$NZ30)/$O30 -> 0 | Y30: =+X30*O30 -> 0 | CO30: 4 | CP30: 4 | CQ30: 4
B31: =+B30 -> 1 | C31: =+C30+1 -> 10 | D31: 0 | E31: =B31&"."&C31&"."&D31 -> 1.10.0 | F31: E2N East Stone FT15 Connection Detail | G31: 2 | H31: MYA | I31: A | J31: 1 | K31: 1 | L31: =+J31-K31 -> 0 | M31: 2 | N31: 6 | O31: =+N31*M31 -> 12 | P31: =+SUM(AA31:NZ31) -> 12 | Q31: =+O31-P31 -> 0 | R31: 45992 | S31: 5 | T31: =IF(S31<>"",IF($Z$9="x",WORKDAY(IF(WEEKDAY(R31,1)=7,R31+2,IF(WEEKDAY(R31,1)=1,R31+1,R31)),S31-1),R31+S31-1),"") -> 45996 | U31: =+K31/J31 -> 1 | V31: =+U31*O31 -> 12 | W31: =SUMIFS($AA31:$NZ31, $AA$8:$NZ$8, $W$12)/$O31 -> 0 | X31: =SUMIF($AA$9:$NZ$9, "<=" & $W$11,$AA31:$NZ31)/$O31 -> 1 | Y31: =+X31*O31 -> 12 | AH31: 2 | AI31: 2 | AJ31: 2 | AK31: 2 | AL31: 2 | AM31: 2
B32: =+B31 -> 1 | C32: =+C31+1 -> 11 | D32: 0 | E32: =B32&"."&C32&"."&D32 -> 1.11.0 | F32: General – Glass replacement | G32: 2,3,4 | H32: MYA | I32: B | J32: 9 | K32: 0 | L32: =+J32-K32 -> 9 | M32: 4 | N32: 5 | O32: =+N32*M32 -> 20 | P32: =+SUM(AA32:NZ32) -> 0 | Q32: =+O32-P32 -> 20 | T32: =IF(S32<>"",IF($Z$9="x",WORKDAY(IF(WEEKDAY(R32,1)=7,R32+2,IF(WEEKDAY(R32,1)=1,R32+1,R32)),S32-1),R32+S32-1),"") | U32: =+K32/J32 -> 0 | V32: =+U32*O32 -> 0 | W32: =SUMIFS($AA32:$NZ32, $AA$8:$NZ$8, $W$12)/$O32 -> 0 | X32: =SUMIF($AA$9:$NZ$9, "<=" & $W$11,$AA32:$NZ32)/$O32 -> 0 | Y32: =+X32*O32 -> 0
B33: =+B32 -> 1 | C33: =+C32+1 -> 12 | D33: 0 | E33: =B33&"."&C33&"."&D33 -> 1.12.0 | F33: FT-18 | O33: =SUM(O34:O35) -> 504 | T33: =IF(S33<>"",IF($Z$9="x",WORKDAY(IF(WEEKDAY(R33,1)=7,R33+2,IF(WEEKDAY(R33,1)=1,R33+1,R33)),S33-1),R33+S33-1),"") | U33: =+SUMPRODUCT(U34:U35,O34:O35)/O33 -> 0 | V33: =+U33*O33 -> 0 | W33: =SUMIFS($AA33:$NZ33, $AA$8:$NZ$8, $W$12)/$O33 -> 0 | X33: =SUMIF($AA$9:$NZ$9, "<=" & $W$11,$AA33:$NZ33)/$O33 -> 0 | Y33: =+X33*O33 -> 0
B34: =+B33 -> 1 | C34: =+C33 -> 12 | D34: 1 | E34: =B34&"."&C34&"."&D34 -> 1.12.1 | F34: Paint repair and bolt replacement | G34: 2.5 | H34: MYA | I34: A | J34: 1 | K34: 0 | L34: =+J34-K34 -> 1 | M34: 10 | N34: 48 | O34: =+N34*M34 -> 480 | P34: =+SUM(AA34:NZ34) -> 480 | Q34: =+O34-P34 -> 0 | R34: 46055 | S34: 40 | T34: =IF(S34<>"",IF($Z$9="x",WORKDAY(IF(WEEKDAY(R34,1)=7,R34+2,IF(WEEKDAY(R34,1)=1,R34+1,R34)),S34-1),R34+S34-1),"") -> 46108 | U34: =+K34/J34 -> 0 | V34: =+U34*O34 -> 0 | W34: =SUMIFS($AA34:$NZ34, $AA$8:$NZ$8, $W$12)/$O34 -> 0 | X34: =SUMIF($AA$9:$NZ$9, "<=" & $W$11,$AA34:$NZ34)/$O34 -> 0 | Y34: =+X34*O34 -> 0 | CS34: 10 | CT34: 10 | CU34: 10 | CV34: 10 | CW34: 10 | CX34: 10 | CZ34: 10 | DA34: 10 | DB34: 10 | DC34: 10 | DD34: 10 | DE34: 10 | DG34: 10 | DH34: 10 | DI34: 10 | DJ34: 10 | DK34: 10 | DL34: 10 | DN34: 10 | DO34: 10 | DP34: 10 | DQ34: 10 | DR34: 10 | DS34: 10 | DU34: 10 | DV34: 10 | DW34: 10 | DX34: 10 | DY34: 10 | DZ34: 10 | EB34: 10 | EC34: 10 | ED34: 10 | EE34: 10 | EF34: 10 | EG34: 10 | EI34: 10 | EJ34: 10 | EK34: 10 | EL34: 10 | EM34: 10 | EN34: 10 | EP34: 10 | EQ34: 10 | ER34: 10 | ES34: 10 | ET34: 10 | EU34: 10
B35: =+B34 -> 1 | C35: =+C34 -> 12 | D35: 2 | E35: =B35&"."&C35&"."&D35 -> 1.12.2 | F35: 1141 Parcel / Passage and parapet installation (NTA) | G35: 2,3,4,5 | H35: MYA | I35: B | J35: 1 | K35: 0 | L35: =+J35-K35 -> 1 | M35: 4 | N35: 6 | O35: =+N35*M35 -> 24 | P35: =+SUM(AA35:NZ35) -> 24 | Q35: =+O35-P35 -> 0 | R35: 46062 | S35: 5 | T35: =IF(S35<>"",IF($Z$9="x",WORKDAY(IF(WEEKDAY(R35,1)=7,R35+2,IF(WEEKDAY(R35,1)=1,R35+1,R35)),S35-1),R35+S35-1),"") -> 46066 | U35: =+K35/J35 -> 0 | V35: =+U35*O35 -> 0 | W35: =SUMIFS($AA35:$NZ35, $AA$8:$NZ$8, $W$12)/$O35 -> 0 | X35: =SUMIF($AA$9:$NZ$9, "<=" & $W$11,$AA35:$NZ35)/$O35 -> 0 | Y35: =+X35*O35 -> 0 | CZ35: 4 | DA35: 4 | DB35: 4 | DC35: 4 | DD35: 4 | DE35: 4
B36: =+B35 -> 1 | C36: =+C35+1 -> 13 | D36: 0 | E36: =B36&"."&C36&"."&D36 -> 1.13.0 | F36: Acoustic Roof FT-18 (NTA) | O36: =SUM(O37:O39) -> 252 | T36: =IF(S36<>"",IF($Z$9="x",WORKDAY(IF(WEEKDAY(R36,1)=7,R36+2,IF(WEEKDAY(R36,1)=1,R36+1,R36)),S36-1),R36+S36-1),"") | U36: =+SUMPRODUCT(U37:U38,O37:O38)/O36 -> 0 | V36: =+U36*O36 -> 0 | W36: =SUMIFS($AA36:$NZ36, $AA$8:$NZ$8, $W$12)/$O36 -> 0 | X36: =SUMIF($AA$9:$NZ$9, "<=" & $W$11,$AA36:$NZ36)/$O36 -> 0 | Y36: =+X36*O36 -> 0
B37: =+B36 -> 1 | C37: =+C36 -> 13 | D37: =+D36+1 -> 1 | E37: =B37&"."&C37&"."&D37 -> 1.13.1 | F37: Installed Steel Drilling + Paint Touch up | G37: 2,3,4,5 | H37: MYA | I37: C | J37: 1 | K37: 0 | L37: =+J37-K37 -> 1 | M37: 4 | N37: 18 | O37: =+N37*M37 -> 72 | P37: =+SUM(AA37:NZ37) -> 72 | Q37: =+O37-P37 -> 0 | R37: 46076 | S37: 15 | T37: =IF(S37<>"",IF($Z$9="x",WORKDAY(IF(WEEKDAY(R37,1)=7,R37+2,IF(WEEKDAY(R37,1)=1,R37+1,R37)),S37-1),R37+S37-1),"") -> 46094 | U37: =+K37/J37 -> 0 | V37: =+U37*O37 -> 0 | W37: =SUMIFS($AA37:$NZ37, $AA$8:$NZ$8, $W$12)/$O37 -> 0 | X37: =SUMIF($AA$9:$NZ$9, "<=" & $W$11,$AA37:$NZ37)/$O37 -> 0 | Y37: =+X37*O37 -> 0 | DN37: 4 | DO37: 4 | DP37: 4 | DQ37: 4 | DR37: 4 | DS37: 4 | DU37: 4 | DV37: 4 | DW37: 4 | DX37: 4 | DY37: 4 | DZ37: 4 | EB37: 4 | EC37: 4 | ED37: 4 | EE37: 4 | EF37: 4 | EG37: 4
B38: =+B37 -> 1 | C38: =+C37 -> 13 | D38: =+D37+1 -> 2 | E38: =B38&"."&C38&"."&D38 -> 1.13.2 | F38: Acoustic Roof Secondary Steel Installation | G38: 2,3,4,5 | H38: MYA | I38: C | J38: 1 | K38: 0 | L38: =+J38-K38 -> 1 | M38: 4 | N38: 18 | O38: =+N38*M38 -> 72 | P38: =+SUM(AA38:NZ38) -> 72 | Q38: =+O38-P38 -> 0 | R38: 46090 | S38: 15 | T38: =IF(S38<>"",IF($Z$9="x",WORKDAY(IF(WEEKDAY(R38,1)=7,R38+2,IF(WEEKDAY(R38,1)=1,R38+1,R38)),S38-1),R38+S38-1),"") -> 46108 | U38: =+K38/J38 -> 0 | V38: =+U38*O38 -> 0 | W38: =SUMIFS($AA38:$NZ38, $AA$8:$NZ$8, $W$12)/$O38 -> 0 | X38: =SUMIF($AA$9:$NZ$9, "<=" & $W$11,$AA38:$NZ38)/$O38 -> 0 | Y38: =+X38*O38 -> 0 | EB38: 4 | EC38: 4 | ED38: 4 | EE38: 4 | EF38: 4 | EG38: 4 | EI38: 4 | EJ38: 4 | EK38: 4 | EL38: 4 | EM38: 4 | EN38: 4 | EP38: 4 | EQ38: 4 | ER38: 4 | ES38: 4 | ET38: 4 | EU38: 4
B39: =+B38 -> 1 | C39: =+C38 -> 13 | D39: =+D38+1 -> 3 | E39: =B39&"."&C39&"."&D39 -> 1.13.3 | F39: Modül installation | G39: 2,3,4,5 | H39: MYA | I39: C | J39: 1 | K39: 0 | L39: =+J39-K39 -> 1 | M39: 6 | N39: 18 | O39: =+N39*M39 -> 108 | P39: =+SUM(AA39:NZ39) -> 108 | Q39: =+O39-P39 -> 0 | R39: 46097 | S39: 15 | T39: =IF(S39<>"",IF($Z$9="x",WORKDAY(IF(WEEKDAY(R39,1)=7,R39+2,IF(WEEKDAY(R39,1)=1,R39+1,R39)),S39-1),R39+S39-1),"") -> 46115 | U39: =+K39/J39 -> 0 | V39: =+U39*O39 -> 0 | W39: =SUMIFS($AA39:$NZ39, $AA$8:$NZ$8, $W$12)/$O39 -> 0 | X39: =SUMIF($AA$9:$NZ$9, "<=" & $W$11,$AA39:$NZ39)/$O39 -> 0 | Y39: =+X39*O39 -> 0 | EI39: 6 | EJ39: 6 | EK39: 6 | EL39: 6 | EM39: 6 | EN39: 6 | EP39: 6 | EQ39: 6 | ER39: 6 | ES39: 6 | ET39: 6 | EU39: 6 | EW39: 6 | EX39: 6 | EY39: 6 | EZ39: 6 | FA39: 6 | FB39: 6
B40: =+B39 -> 1 | C40: =+C39+1 -> 14 | D40: 0 | E40: =B40&"."&C40&"."&D40 -> 1.14.0 | F40: Documentation + Testing | T40: =IF(S40<>"",IF($Z$9="x",WORKDAY(IF(WEEKDAY(R40,1)=7,R40+2,IF(WEEKDAY(R40,1)=1,R40+1,R40)),S40-1),R40+S40-1),"") | V40: =+U40*O40 -> 0 | Y40: =+X40*O40 -> 0
B41: =+B40 -> 1 | C41: =+C40 -> 14 | D41: =+D40+1 -> 1 | E41: =B41&"."&C41&"."&D41 -> 1.14.1 | F41: WT01 | H41: MYA | M41: 0 | N41: 0 | O41: =+N41*M41 -> 0 | T41: =IF(S41<>"",IF($Z$9="x",WORKDAY(IF(WEEKDAY(R41,1)=7,R41+2,IF(WEEKDAY(R41,1)=1,R41+1,R41)),S41-1),R41+S41-1),"") | V41: =+U41*O41 -> 0 | Y41: =+X41*O41 -> 0
B42: =+B41 -> 1 | C42: =+C41 -> 14 | D42: =+D41+1 -> 2 | E42: =B42&"."&C42&"."&D42 -> 1.14.2 | F42: FT08 | H42: MYA | M42: 0 | N42: 0 | O42: =+N42*M42 -> 0 | T42: =IF(S42<>"",IF($Z$9="x",WORKDAY(IF(WEEKDAY(R42,1)=7,R42+2,IF(WEEKDAY(R42,1)=1,R42+1,R42)),S42-1),R42+S42-1),"") | V42: =+U42*O42 -> 0 | Y42: =+X42*O42 -> 0
B43: =+B42 -> 1 | C43: =+C42 -> 14 | D43: =+D42+1 -> 3 | E43: =B43&"."&C43&"."&D43 -> 1.14.3 | F43: FT07 | H43: MYA | M43: 0 | N43: 0 | O43: =+N43*M43 -> 0 | T43: =IF(S43<>"",IF($Z$9="x",WORKDAY(IF(WEEKDAY(R43,1)=7,R43+2,IF(WEEKDAY(R43,1)=1,R43+1,R43)),S43-1),R43+S43-1),"") | V43: =+U43*O43 -> 0 | Y43: =+X43*O43 -> 0
...

Sheet 260113_E2NS Terminplan
Z4: 45931 | AA4: =TEXT(AD9,"MMMM JJ") -> November 25 | AH4: =TEXT(AM9,"MMMM JJ") -> December 25 | AO4: =TEXT(AT9,"MMMM JJ") -> December 25 | AV4: =TEXT(BA9,"MMMM JJ") -> December 25 | BC4: =TEXT(BH9,"MMMM JJ") -> December 25 | BJ4: =TEXT(BO9,"MMMM JJ") -> January 26 | BQ4: =TEXT(BV9,"MMMM JJ") -> January 26 | BX4: =TEXT(CC9,"MMMM JJ") -> January 26 | CE4: =TEXT(CJ9,"MMMM JJ") -> January 26 | CL4: =TEXT(CQ9,"MMMM JJ") -> January 26 | CS4: =TEXT(CX9,"MMMM JJ") -> February 26 | CZ4: =TEXT(DE9,"MMMM JJ") -> February 26 | DG4: =TEXT(DL9,"MMMM JJ") -> February 26 | DN4: =TEXT(DS9,"MMMM JJ") -> February 26 | DU4: =TEXT(DZ9,"MMMM JJ") -> March 26 | EB4: =TEXT(EG9,"MMMM JJ") -> March 26 | EI4: =TEXT(EN9,"MMMM JJ") -> March 26 | EP4: =TEXT(EU9,"MMMM JJ") -> March 26 | EW4: =TEXT(FB9,"MMMM JJ") -> April 26 | FD4: =TEXT(FI9,"MMMM JJ") -> April 26 | FK4: =TEXT(FP9,"MMMM JJ") -> April 26 | FR4: =TEXT(FW9,"MMMM JJ") -> April 26 | FY4: =TEXT(GD9,"MMMM JJ") -> May 26 | GF4: =TEXT(GK9,"MMMM JJ") -> May 26 | GM4: =TEXT(GR9,"MMMM JJ") -> May 26 | GT4: =TEXT(GY9,"MMMM JJ") -> May 26 | HA4: =TEXT(HF9,"MMMM JJ") -> May 26 | HH4: =TEXT(HM9,"MMMM JJ") -> June 26 | HO4: =TEXT(HT9,"MMMM JJ") -> June 26 | HV4: =TEXT(IA9,"MMMM JJ") -> June 26 | IC4: =TEXT(IH9,"MMMM JJ") -> June 26 | IJ4: =TEXT(IO9,"MMMM JJ") -> July 26 | IQ4: =TEXT(IV9,"MMMM JJ") -> July 26 | IX4: =TEXT(JC9,"MMMM JJ") -> July 26 | JE4: =TEXT(JJ9,"MMMM JJ") -> July 26 | JL4: =TEXT(JQ9,"MMMM JJ") -> August 26 | JS4: =TEXT(JX9,"MMMM JJ") -> August 26 | JZ4: =TEXT(KE9,"MMMM JJ") -> August 26 | KG4: =TEXT(KL9,"MMMM JJ") -> August 26 | KN4: =TEXT(KS9,"MMMM JJ") -> August 26 | KU4: =TEXT(KZ9,"MMMM JJ") -> September 26 | LB4: =TEXT(LG9,"MMMM JJ") -> September 26 | LI4: =TEXT(LN9,"MMMM JJ") -> September 26 | LP4: =TEXT(LU9,"MMMM JJ") -> September 26 | LW4: =TEXT(MB9,"MMMM JJ") -> October 26 | MD4: =TEXT(MI9,"MMMM JJ") -> October 26 | MK4: =TEXT(MP9,"MMMM JJ") -> October 26 | MR4: =TEXT(MW9,"MMMM JJ") -> October 26 | MY4: =TEXT(ND9,"MMMM JJ") -> October 26 | NF4: =TEXT(NK9,"MMMM JJ") -> November 26 | NM4: =TEXT(NR9,"MMMM JJ") -> November 26 | NT4: =TEXT(NY9,"MMMM JJ") -> November 26
R5: E2NS | AA5: =WEEKNUM(AF9,21) -> 48 | AH5: =WEEKNUM(AM9,21) -> 49 | AO5: =WEEKNUM(AT9,21) -> 50 | AV5: =WEEKNUM(BA9,21) -> 51 | BC5: =WEEKNUM(BH9,21) -> 52 | BJ5: =WEEKNUM(BO9,21) -> 1 | BQ5: =WEEKNUM(BV9,21) -> 2 | BX5: =WEEKNUM(CC9,21) -> 3 | CE5: =WEEKNUM(CJ9,21) -> 4 | CL5: =WEEKNUM(CQ9,21) -> 5 | CS5: =WEEKNUM(CX9,21) -> 6 | CZ5: =WEEKNUM(DE9,21) -> 7 | DG5: =WEEKNUM(DL9,21) -> 8 | DN5: =WEEKNUM(DS9,21) -> 9 | DU5: =WEEKNUM(DZ9,21) -> 10 | EB5: =WEEKNUM(EG9,21) -> 11 | EI5: =WEEKNUM(EN9,21) -> 12 | EP5: =WEEKNUM(EU9,21) -> 13 | EW5: =WEEKNUM(FB9,21) -> 14 | FD5: =WEEKNUM(FI9,21) -> 15 | FK5: =WEEKNUM(FP9,21) -> 16 | FR5: =WEEKNUM(FW9,21) -> 17 | FY5: =WEEKNUM(GD9,21) -> 18 | GF5: =WEEKNUM(GK9,21) -> 19 | GM5: =WEEKNUM(GR9,21) -> 20 | GT5: =WEEKNUM(GY9,21) -> 21 | HA5: =WEEKNUM(HF9,21) -> 22 | HH5: =WEEKNUM(HM9,21) -> 23 | HO5: =WEEKNUM(HT9,21) -> 24 | HV5: =WEEKNUM(IA9,21) -> 25 | IC5: =WEEKNUM(IH9,21) -> 26 | IJ5: =WEEKNUM(IO9,21) -> 27 | IQ5: =WEEKNUM(IV9,21) -> 28 | IX5: =WEEKNUM(JC9,21) -> 29 | JE5: =WEEKNUM(JJ9,21) -> 30 | JL5: =WEEKNUM(JQ9,21) -> 31 | JS5: =WEEKNUM(JX9,21) -> 32 | JZ5: =WEEKNUM(KE9,21) -> 33 | KG5: =WEEKNUM(KL9,21) -> 34 | KN5: =WEEKNUM(KS9,21) -> 35 | KU5: =WEEKNUM(KZ9,21) -> 36 | LB5: =WEEKNUM(LG9,21) -> 37 | LI5: =WEEKNUM(LN9,21) -> 38 | LP5: =WEEKNUM(LU9,21) -> 39 | LW5: =WEEKNUM(MB9,21) -> 40 | MD5: =WEEKNUM(MI9,21) -> 41 | MK5: =WEEKNUM(MP9,21) -> 42 | MR5: =WEEKNUM(MW9,21) -> 43 | MY5: =WEEKNUM(ND9,21) -> 44 | NF5: =WEEKNUM(NK9,21) -> 45 | NM5: =WEEKNUM(NR9,21) -> 46 | NT5: =WEEKNUM(NY9,21) -> 47
AA6: 41 | AB6: 42 | AC6: 43 | AD6: 44 | AE6: 45 | AF6: 46 | AG6: 47 | AH6: 48 | AI6: 49 | AJ6: 50 | AK6: 51 | AL6: 52 | AM6: 53 | AN6: 54 | AO6: 55 | AP6: 56 | AQ6: 57 | AR6: 58 | AS6: 59 | AT6: 60 | AU6: 61 | AV6: 62 | AW6: 63 | AX6: 64 | AY6: 65 | AZ6: 66 | BA6: 67 | BB6: 68 | BC6: 69 | BD6: 70 | BE6: 71 | BF6: 72 | BG6: 73 | BH6: 74 | BI6: 75 | BJ6: 76 | BK6: 77 | BL6: 78 | BM6: 79 | BN6: 80 | BO6: 81 | BP6: 82 | BQ6: 83 | BR6: 84 | BS6: 85 | BT6: 86 | BU6: 87 | BV6: 88 | BW6: 89 | BX6: 90 | BY6: 91 | BZ6: 92 | CA6: 93 | CB6: 94 | CC6: 95 | CD6: 96 | CE6: 97 | CF6: 98 | CG6: 99 | CH6: 100 | CI6: 101 | CJ6: 102 | CK6: 103 | CL6: 104 | CM6: 105 | CN6: 106 | CO6: 107 | CP6: 108 | CQ6: 109 | CR6: 110 | CS6: 111 | CT6: 112 | CU6: 113 | CV6: 114 | CW6: 115 | CX6: 116 | CY6: 117 | CZ6: 118 | DA6: 119 | DB6: 120 | DC6: 121 | DD6: 122 | DE6: 123 | DF6: 124 | DG6: 125 | DH6: 126 | DI6: 127 | DJ6: 128 | DK6: 129 | DL6: 130 | DM6: 131 | DN6: 132 | DO6: 133 | DP6: 134 | DQ6: 135 | DR6: 136 | DS6: 137 | DT6: 138 | DU6: 139 | DV6: 140 | DW6: 141 | DX6: 142 | DY6: 143 | DZ6: 144 | EA6: 145 | EB6: 146 | EC6: 147 | ED6: 148 | EE6: 149 | EG6: 151 | EH6: 152 | EI6: 153 | EJ6: 154 | EK6: 155 | EL6: 156 | EM6: 157 | EN6: 158 | EO6: 159 | EP6: 160 | EQ6: 161 | ER6: 162 | ES6: 163 | ET6: 164 | EU6: 165 | EV6: 166 | EW6: 167 | EX6: 168 | EY6: 169 | EZ6: 170 | FA6: 171 | FB6: 172 | FC6: 173 | FD6: 174 | FE6: 175 | FF6: 176 | FG6: 177 | FH6: 178 | FI6: 179 | FJ6: 180 | FK6: 181 | FL6: 182 | FM6: 183 | FN6: 184 | FO6: 185 | FP6: 186 | FQ6: 187 | FR6: 188 | FS6: 189 | FT6: 190 | FU6: 191 | FV6: 192 | FW6: 193 | FX6: 194 | FY6: 195 | FZ6: 196 | GA6: 197 | GB6: 198 | GC6: 199 | GD6: 200 | GE6: 201 | GF6: 202 | GG6: 203 | GH6: 204 | GI6: 205 | GJ6: 206 | GK6: 207 | GL6: 208 | GM6: 209 | GN6: 210 | GO6: 211 | GP6: 212 | GQ6: 213 | GR6: 214 | GS6: 215 | GT6: 216 | GU6: 217 | GV6: 218 | GW6: 219 | GX6: 220 | GY6: 221 | GZ6: 222 | HA6: 223 | HB6: 224 | HC6: 225 | HD6: 226 | HE6: 227 | HF6: 228 | HG6: 229 | HH6: 230 | HI6: 231 | HJ6: 232 | HK6: 233 | HL6: 234 | HM6: 235 | HN6: 236 | HO6: 237 | HP6: 238 | HQ6: 239 | HR6: 240 | HS6: 241 | HT6: 242 | HU6: 243 | HV6: 244 | HW6: 245 | HX6: 246 | HY6: 247 | HZ6: 248 | IA6: 249 | IB6: 250 | IC6: 251 | ID6: 252 | IE6: 253 | IF6: 254 | IG6: 255 | IH6: 256 | II6: 257 | IJ6: 258 | IK6: 259 | IL6: 260 | IM6: 261 | IN6: 262 | IO6: 263 | IP6: 264 | IQ6: 265 | IR6: 266 | IS6: 267 | IT6: 268 | IU6: 269 | IV6: 270 | IW6: 271 | IX6: 272 | IY6: 273 | IZ6: 274 | JA6: 275 | JB6: 276 | JC6: 277 | JD6: 278 | JE6: 279 | JF6: 280 | JG6: 281 | JH6: 282 | JI6: 283 | JJ6: 284 | JK6: 285 | JL6: 286 | JM6: 287 | JN6: 288 | JO6: 289 | JP6: 290 | JQ6: 291 | JR6: 292 | JS6: 293 | JT6: 294 | JU6: 295 | JV6: 296 | JW6: 297 | JX6: 298 | JY6: 299 | JZ6: 300 | KA6: 301 | KB6: 302 | KC6: 303 | KD6: 304 | KE6: 305 | KF6: 306 | KG6: 307 | KH6: 308 | KI6: 309 | KJ6: 310 | KK6: 311 | KL6: 312 | KM6: 313 | KN6: 314 | KO6: 315 | KP6: 316 | KQ6: 317 | KR6: 318 | KS6: 319 | KT6: 320 | KU6: 321 | KV6: 322 | KW6: 323 | KX6: 324 | KY6: 325 | KZ6: 326 | LA6: 327 | LB6: 328 | LC6: 329 | LD6: 330 | LE6: 331 | LF6: 332 | LG6: 333 | LH6: 334 | LI6: 335 | LJ6: 336 | LK6: 337 | LL6: 338 | LM6: 339 | LN6: 340 | LO6: 341 | LP6: 342 | LQ6: 343 | LR6: 344 | LS6: 345 | LT6: 346 | LU6: 347 | LV6: 348 | LW6: 349 | LX6: 350 | LY6: 351 | LZ6: 352 | MA6: 353 | MB6: 354 | MC6: 355 | MD6: 356 | ME6: 357 | MF6: 358 | MG6: 359 | MH6: 360 | MI6: 361 | MJ6: 362 | MK6: 363 | ML6: 364 | MM6: 365 | MN6: 366 | MO6: 367 | MP6: 368 | MQ6: 369 | MR6: 370 | MS6: 371 | MT6: 372 | MU6: 373 | MV6: 374 | MW6: 375 | MX6: 376 | MY6: 377 | MZ6: 378 | NA6: 379 | NB6: 380 | NC6: 381 | ND6: 382 | NE6: 383 | NF6: 384 | NG6: 385 | NH6: 386 | NI6: 387 | NJ6: 388 | NK6: 389 | NL6: 390 | NM6: 391 | NN6: 392 | NO6: 393 | NP6: 394 | NQ6: 395 | NR6: 396 | NS6: 397 | NT6: 398 | NU6: 399 | NV6: 400 | NW6: 401 | NX6: 402 | NY6: 403 | NZ6: 404
AA7: =TEXT(AA9,"TTT") -> Mon | AB7: =TEXT(AB9,"TTT") -> Tue | AC7: =TEXT(AC9,"TTT") -> Wed | AD7: =TEXT(AD9,"TTT") -> Thu | AE7: =TEXT(AE9,"TTT") -> Fri | AF7: =TEXT(AF9,"TTT") -> Sat | AG7: =TEXT(AG9,"TTT") -> Sun | AH7: =TEXT(AH9,"TTT") -> Mon | ... NZ7: =TEXT(NZ9,"TTT") -> Sun
AA8: =+_xlfn.ISOWEEKNUM(AA9) -> 48 | AB8: =+_xlfn.ISOWEEKNUM(AB9) -> 48 | AC8: =+_xlfn.ISOWEEKNUM(AC9) -> 48 | AD8: =+_xlfn.ISOWEEKNUM(AD9) -> 48 | AE8: =+_xlfn.ISOWEEKNUM(AE9) -> 48 | AF8: =+_xlfn.ISOWEEKNUM(AF9) -> 48 | AG8: =+_xlfn.ISOWEEKNUM(AG9) -> 48 | AH8: =+_xlfn.ISOWEEKNUM(AH9) -> 49 | ... NZ8: =+_xlfn.ISOWEEKNUM(NZ9) -> 47
Z9: x | AA9: 45985 | AB9: =AA9+1 -> 45986 | AC9: =AB9+1 -> 45987 | AD9: =AC9+1 -> 45988 | AE9: =AD9+1 -> 45989 | AF9: =AE9+1 -> 45990 | AG9: =AF9+1 -> 45991 | AH9: =AG9+1 -> 45992 | AI9: =AH9+1 -> 45993 | ... NZ9: =NY9+1 -> 46348
E10: Pos. | F10: Aufgabe/Tätigkeit | G10: Presequities | H10: Responsible | I10: Group | J10: QTY | K10: Done | L10: Rem. | M10: Manpower | N10: Duration | O10: Total Manday | R10: Beginn [Datum] | S10: =IF($Z$9="x","Ende nach [AT]","Endet nach [Tagen]") -> Ende nach [AT] | T10: Ende [Datum] | U10: Status | W10: =+"KW"&W13&" Progress" -> KW2 Progress | X10: =+"Cumulative Progress =<"&"KW"&W13 -> Cumulative Progress =<KW2 | Z10: Anmerkungen | AG10: µ | AL10: µ | AM10: µ | AN10: µ | AU10: µ | AZ10: µ | BA10: µ | BB10: µ
O11: =+O13+O46+O90+O126 -> 4169 | U11: =+(O13*U13+O46*U46+O90*U90+O126*U126)/O11 -> 0.088484642 | W11: =HLOOKUP(W13,AA8:PLB9,2,FALSE)+6 -> 46033 | AA11: =SUM(AA14:AA181) -> 15 | AB11: =SUM(AB14:AB181) -> 13 | AC11: =SUM(AC14:AC181) -> 15 | AD11: =SUM(AD14:AD181) -> 15 | AE11: =SUM(AE14:AE181) -> 15 | AF11: =SUM(AF14:AF181) -> 15 | AG11: =SUM(AG14:AG181) -> 0 | AH11: =SUM(AH14:AH181) -> 19 | ... HG11: =SUM(HG14:HG181) -> 0
BX12: =+BX11-BX35-BX84 -> 20 | BY12: =+BY11-BY35-BY84 -> 20 | BZ12: =+BZ11-BZ35-BZ84 -> 20 | CA12: =+CA11-CA35-CA84 -> 20 | CB12: =+CB11-CB35-CB84 -> 20 | CC12: =+CC11-CC35-CC84 -> 20 | CE12: =+CE11-CE35-CE84 -> 20 | CF12: =+CF11-CF35-CF84 -> 20 | CG12: =+CG11-CG35-CG84 -> 20 | CH12: =+CH11-CH35-CH84 -> 20 | CI12: =+CI11-CI35-CI84 -> 20 | CJ12: =+CJ11-CJ35-CJ84 -> 20 | CL12: =+CL11-CL35-CL84 -> 20 | CM12: =+CM11-CM35-CM84 -> 20 | CN12: =+CN11-CN35-CN84 -> 20 | CO12: =+CO11-CO35-CO84 -> 20 | CP12: =+CP11-CP35-CP84 -> 20 | CQ12: =+CQ11-CQ35-CQ84 -> 20 | CS12: =+CS11-CS35-CS84 -> 26 | CT12: =+CT11-CT35-CT84 -> 26 | CU12: =+CU11-CU35-CU84 -> 26 | CV12: =+CV11-CV35-CV84 -> 26 | CW12: =+CW11-CW35-CW84 -> 26 | CX12: =+CX11-CX35-CX84 -> 26 | CZ12: =+CZ11-CZ35-CZ84 -> 25 | DA12: =+DA11-DA35-DA84 -> 25 | DB12: =+DB11-DB35-DB84 -> 25 | DC12: =+DC11-DC35-DC84 -> 25 | DD12: =+DD11-DD35-DD84 -> 25 | DE12: =+DE11-DE35-DE84 -> 25 | DG12: =+DG11-DG35-DG84 -> 23 | DH12: =+DH11-DH35-DH84 -> 23 | DI12: =+DI11-DI35-DI84 -> 23 | DJ12: =+DJ11-DJ35-DJ84 -> 23 | DK12: =+DK11-DK35-DK84 -> 23 | DL12: =+DL11-DL35-DL84 -> 23 | DN12: =+DN11-DN35-DN84 -> 23 | DO12: =+DO11-DO35-DO84 -> 23 | DP12: =+DP11-DP35-DP84 -> 23 | DQ12: =+DQ11-DQ35-DQ84 -> 23 | DR12: =+DR11-DR35-DR84 -> 23 | DS12: =+DS11-DS35-DS84 -> 17 | DU12: =+DU11-DU35-DU84 -> 31 | DV12: =+DV11-DV35-DV84 -> 31 | DW12: =+DW11-DW35-DW84 -> 31 | DX12: =+DX11-DX35-DX84 -> 31 | DY12: =+DY11-DY35-DY84 -> 31 | DZ12: =+DZ11-DZ35-DZ84 -> 31 | EB12: =+EB11-EB35-EB84 -> 26 | EC12: =+EC11-EC35-EC84 -> 26 | ED12: =+ED11-ED35-ED84 -> 26 | EE12: =+EE11-EE35-EE84 -> 26 | EF12: =+EF11-EF35-EF84 -> 26 | EG12: =+EG11-EG35-EG84 -> 26 | EI12: =+EI11-EI35-EI84 -> 31 | EJ12: =+EJ11-EJ35-EJ84 -> 31 | EK12: =+EK11-EK35-EK84 -> 31 | EL12: =+EL11-EL35-EL84 -> 35 | EM12: =+EM11-EM35-EM84 -> 35 | EN12: =+EN11-EN35-EN84 -> 35 | EP12: =+EP11-EP35-EP84 -> 41 | EQ12: =+EQ11-EQ35-EQ84 -> 41 | ER12: =+ER11-ER35-ER84 -> 41 | ES12: =+ES11-ES35-ES84 -> 41 | ET12: =+ET11-ET35-ET84 -> 41 | EU12: =+EU11-EU35-EU84 -> 41 | EW12: =+EW11-EW35-EW84 -> 48 | EX12: =+EX11-EX35-EX84 -> 48 | EY12: =+EY11-EY35-EY84 -> 48 | EZ12: =+EZ11-EZ35-EZ84 -> 48 | FA12: =+FA11-FA35-FA84 -> 45 | FB12: =+FB11-FB35-FB84 -> 45
B13: 1 | C13: 0 | D13: 0 | E13: =B13&"."&C13&"."&D13 -> 1.0.0 | F13: E2 N | O13: =+SUM(O14,O19,O23,O24,O27:O34,O37) -> 1610 | T13: =+MAX(T14:T45) -> 46115 | U13: =+SUM(O14*U14,O19*U19,O23*U23,O24*U24,SUMPRODUCT(O27:O34,U27:U34),O37*U37)/O13 -> 0.12682542 | V13: =+U13*O13 -> 204.18893 | W13: =+Summary!D4 -> 2 | Y13: =+SUM(Y14,Y19,Y23,Y24,Y27:Y34,Y37) -> 48
B14: =+B13 -> 1 | C14: 1 | D14: 0 | E14: =B14&"."&C14&"."&D14 -> 1.1.0 | F14: E2N Outside Windows | O14: =SUM(O15:O18) -> 540 | T14: =IF(S14<>"",IF(#REF!="x",WORKDAY(IF(WEEKDAY(R14,1)=7,R14+2,IF(WEEKDAY(R14,1)=1,R14+1,R14)),S14-1),R14+S14-1),"") | U14: =+SUMPRODUCT(U15:U18,O15:O18)/O14 -> 0.02374169 | V14: =+U14*O14 -> 12.820513 | Y14: =+X14*O14 -> 0
B15: =+B14 -> 1 | C15: 1 | D15: 1 | E15: =B15&"."&C15&"."&D15 -> 1.1.1 | F15: Dismantling of Drywall + Al Sheet | G15: 1 | H15: MYA | I15: A | J15: 156 | K15: 8 | L15: =+J15-K15 -> 148 | M15: 2 | N15: 125 | O15: =+N15*M15 -> 250 | P15: =+SUM(AA15:NZ15) -> 250 | Q15: =+O15-P15 -> 0 | R15: 46034 | S15: 30 | T15: =IF(S15<>"",IF($Z$9="x",WORKDAY(IF(WEEKDAY(R15,1)=7,R15+2,IF(WEEKDAY(R15,1)=1,R15+1,R15)),S15-1),R15+S15-1),"") -> 46073 | U15: =+K15/J15 -> 0.051282051 | V15: =+U15*O15 -> 12.820513 | W15: =SUMIFS($AA15:$NZ15, $AA$8:$NZ$8, $W$13)/$O15 -> 0 | X15: =SUMIF($AA$9:$NZ$9, "<=" & $W$11,$AA15:$NZ15)/$O15 -> 0 | Y15: =+X15*O15 -> 0 | BX15: 4 | BY15: 4 | BZ15: 4 | CA15: 4 | CB15: 4 | CC15: 4 | CE15: 12 | CF15: 12 | CG15: 12 | CH15: 12 | CI15: 12 | CJ15: 12 | CL15: 8 | CM15: 8 | CN15: 8 | CO15: 8 | CP15: 8 | CQ15: 8 | CS15: 8 | CT15: 8 | CU15: 8 | CV15: 8 | CW15: 8 | CX15: 8 | CZ15: 6 | DA15: 6 | DB15: 6 | DC15: 6 | DD15: 6 | DE15: 6 | DG15: 4 | DH15: 4 | DI15: 4 | DJ15: 4 | DK15: 4 | DL15: 2
B16: =+B15 -> 1 | C16: 1 | D16: 2 | E16: =B16&"."&C16&"."&D16 -> 1.1.2 | F16: Application of New Membrane | G16: 1 | H16: MYA | I16: A | J16: =+J15 -> 156 | K16: 0 | L16: =+J16-K16 -> 156 | M16: 2 | N16: 80 | O16: =+N16*M16 -> 160 | P16: =+SUM(AA16:NZ16) -> 160 | Q16: =+O16-P16 -> 0 | R16: =+R15+7 -> 46041 | S16: 30 | T16: =IF(S16<>"",IF($Z$9="x",WORKDAY(IF(WEEKDAY(R16,1)=7,R16+2,IF(WEEKDAY(R16,1)=1,R16+1,R16)),S16-1),R16+S16-1),"") -> 46080 | U16: =+K16/J16 -> 0 | V16: =+U16*O16 -> 0 | W16: =SUMIFS($AA16:$NZ16, $AA$8:$NZ$8, $W$13)/$O16 -> 0 | X16: =SUMIF($AA$9:$NZ$9, "<=" & $W$11,$AA16:$NZ16)/$O16 -> 0 | Y16: =+X16*O16 -> 0 | CE16: 5 | CF16: 5 | CG16: 5 | CH16: 5 | CI16: 5 | CJ16: 5 | CL16: 6 | CM16: 6 | CN16: 6 | CO16: 6 | CP16: 6 | CQ16: 6 | CS16: 4 | CT16: 4 | CU16: 4 | CV16: 4 | CW16: 4 | CX16: 4 | CZ16: 4 | DA16: 4 | DB16: 4 | DC16: 4 | DD16: 4 | DE16: 4 | DG16: 4 | DH16: 4 | DI16: 4 | DJ16: 4 | DK16: 4 | DL16: 6 | DN16: 4 | DO16: 4 | DP16: 4 | DQ16: 4 | DR16: 4
B17: =+B16 -> 1 | C17: 1 | D17: =+D16+1 -> 3 | E17: =B17&"."&C17&"."&D17 -> 1.1.3 | F17: Installation of Al. Sheet | G17: 1 | H17: MYA | I17: A | J17: =+J16 -> 156 | K17: 0 | L17: =+J17-K17 -> 156 | M17: 2 | N17: 65 | O17: =+N17*M17 -> 130 | P17: =+SUM(AA17:NZ17) -> 130 | Q17: =+O17-P17 -> 0 | R17: =+R16+7 -> 46048 | S17: 25 | T17: =IF(S17<>"",IF($Z$9="x",WORKDAY(IF(WEEKDAY(R17,1)=7,R17+2,IF(WEEKDAY(R17,1)=1,R17+1,R17)),S17-1),R17+S17-1),"") -> 46080 | U17: =+K17/J17 -> 0 | V17: =+U17*O17 -> 0 | W17: =SUMIFS($AA17:$NZ17, $AA$8:$NZ$8, $W$13)/$O17 -> 0 | X17: =SUMIF($AA$9:$NZ$9, "<=" & $W$11,$AA17:$NZ17)/$O17 -> 0 | Y17: =+X17*O17 -> 0 | CL17: 4 | CM17: 4 | CN17: 4 | CO17: 4 | CP17: 4 | CQ17: 4 | CS17: 6 | CT17: 6 | CU17: 6 | CV17: 6 | CW17: 6 | CX17: 6 | CZ17: 4 | DA17: 4 | DB17: 4 | DC17: 4 | DD17: 4 | DE17: 4 | DG17: 4 | DH17: 4 | DI17: 4 | DJ17: 4 | DK17: 4 | DL17: 4 | DN17: 4 | DO17: 4 | DP17: 4 | DQ17: 4 | DR17: 4 | DS17: 2
B18: =+B16 -> 1 | C18: 1 | D18: =+D17+1 -> 4 | E18: =B18&"."&C18&"."&D18 -> 1.1.4 | F18: Installation of New Drywall | G18: 1 | H18: XXX | I18: A | J18: =+J16 -> 156 | K18: 0 | L18: =+J18-K18 -> 156 | O18: =+N18*M18 -> 0 | P18: =+SUM(AA18:NZ18) -> 0 | Q18: =+O18-P18 -> 0 | T18: =IF(S18<>"",IF($Z$9="x",WORKDAY(IF(WEEKDAY(R18,1)=7,R18+2,IF(WEEKDAY(R18,1)=1,R18+1,R18)),S18-1),R18+S18-1),"") | U18: =+K18/J18 -> 0 | V18: =+U18*O18 -> 0 | Y18: =+X18*O18 -> 0
B19: =+B18 -> 1 | C19: =+C18+1 -> 2 | D19: 0 | E19: =B19&"."&C19&"."&D19 -> 1.2.0 | F19: E2N Courtyard Windows | O19: =SUM(O20:O22) -> 160 | T19: =IF(S19<>"",IF($Z$9="x",WORKDAY(IF(WEEKDAY(R19,1)=7,R19+2,IF(WEEKDAY(R19,1)=1,R19+1,R19)),S19-1),R19+S19-1),"") | U19: =+SUMPRODUCT(U20:U22,O20:O22)/O19 -> 0.79605263 | V19: =+U19*O19 -> 127.36842 | Y19: =+X19*O19 -> 0
B20: =+B19 -> 1 | C20: =+C19 -> 2 | D20: =+D19+1 -> 1 | E20: =B20&"."&C20&"."&D20 -> 1.2.1 | F20: Dismantling of Drywall | G20: 1 | H20: MYA | I20: A | J20: 76 | K20: 76 | L20: =+J20-K20 -> 0 | M20: 10 | N20: 8 | O20: =+N20*M20 -> 80 | P20: =+SUM(AA20:NZ20) -> 80 | Q20: =+O20-P20 -> 0 | R20: 45985 | S20: 20 | T20: =IF(S20<>"",IF($Z$9="x",WORKDAY(IF(WEEKDAY(R20,1)=7,R20+2,IF(WEEKDAY(R20,1)=1,R20+1,R20)),S20-1),R20+S20-1),"") -> 46010 | U20: =+K20/J20 -> 1 | V20: =+U20*O20 -> 80 | W20: =SUMIFS($AA20:$NZ20, $AA$8:$NZ$8, $W$13)/$O20 -> 0 | X20: =SUMIF($AA$9:$NZ$9, "<=" & $W$11,$AA20:$NZ20)/$O20 -> 1 | Y20: =+X20*O20 -> 80 | AA20: 2 | AB20: 3 | AC20: 3 | AD20: 2 | AE20: 2 | AF20: 2 | AH20: 4 | AI20: 4 | AJ20: 4 | AK20: 4 | AL20: 4 | AM20: 4 | AO20: 4 | AP20: 4 | AQ20: 4 | AR20: 4 | AS20: 4 | AT20: 4 | AV20: 4 | AW20: 4 | AX20: 4 | AY20: 4 | AZ20: 2
B21: =+B20 -> 1 | C21: =+C20 -> 2 | D21: =+D20+1 -> 2 | E21: =B21&"."&C21&"."&D21 -> 1.2.2 | F21: Application of New Membrane | G21: 1 | H21: MYA | I21: A | J21: =+J20 -> 76 | K21: 45 | L21: =+J21-K21 -> 31 | M21: 10 | N21: 8 | O21: =+N21*M21 -> 80 | P21: =+SUM(AA21:NZ21) -> 134 | Q21: =+O21-P21 -> -54 | R21: 45999 | S21: 35 | T21: =IF(S21<>"",IF($Z$9="x",WORKDAY(IF(WEEKDAY(R21,1)=7,R21+2,IF(WEEKDAY(R21,1)=1,R21+1,R21)),S21-1),R21+S21-1),"") -> 46045 | U21: =+K21/J21 -> 0.59210526 | V21: =+U21*O21 -> 47.368421 | W21: =SUMIFS($AA21:$NZ21, $AA$8:$NZ$8, $W$13)/$O21 -> 0 | X21: =SUMIF($AA$9:$NZ$9, "<=" & $W$11,$AA21:$NZ21)/$O21 -> 0.55 | Y21: =+X21*O21 -> 44 | AO21: 4 | AP21: 4 | AQ21: 4 | AR21: 4 | AS21: 4 | AT21: 4 | AV21: 4 | AW21: 4 | AX21: 4 | AY21: 4 | AZ21: 4 | BX21: 14 | BY21: 14 | BZ21: 14 | CA21: 14 | CB21: 14 | CC21: 14 | CE21: 1 | CF21: 1 | CG21: 1 | CH21: 1 | CI21: 1 | CJ21: 1
B22: =+B21 -> 1 | C22: =+C21 -> 2 | D22: =+D21+1 -> 3 | E22: =B22&"."&C22&"."&D22 -> 1.2.3 | F22: Installation of New Drywall | G22: 1 | H22: XXX | I22: A | J22: =+J21 -> 76 | K22: 0 | L22: =+J22-K22 -> 76 | O22: =+N22*M22 -> 0 | P22: =+SUM(AA22:NZ22) -> 0 | Q22: =+O22-P22 -> 0 | T22: =IF(S22<>"",IF($Z$9="x",WORKDAY(IF(WEEKDAY(R22,1)=7,R22+2,IF(WEEKDAY(R22,1)=1,R22+1,R22)),S22-1),R22+S22-1),"") | U22: =+K22/J22 -> 0 | V22: =+U22*O22 -> 0 | Y22: =+X22*O22 -> 0
B23: =+B22 -> 1 | C23: =+C20+1 -> 3 | D23: 0 | E23: =B23&"."&C23&"."&D23 -> 1.3.0 | F23: Garage entrance aluminum cladding (north) | H23: MYA | I23: B | J23: 1 | K23: 1 | L23: =+J23-K23 -> 0 | M23: 4 | N23: 6 | O23: =+N23*M23 -> 24 | R23: 45992 | S23: 5 | T23: =IF(S23<>"",IF($Z$9="x",WORKDAY(IF(WEEKDAY(R23,1)=7,R23+2,IF(WEEKDAY(R23,1)=1,R23+1,R23)),S23-1),R23+S23-1),"") -> 45996 | U23: =+K23/J23 -> 1 | V23: =+U23*O23 -> 24 | W23: =SUMIFS($AA23:$NZ23, $AA$8:$NZ$8, $W$13)/$O23 -> 0 | X23: =SUMIF($AA$9:$NZ$9, "<=" & $W$11,$AA23:$NZ23)/$O23 -> 1 | Y23: =+X23*O23 -> 24 | AH23: 4 | AI23: 4 | AJ23: 4 | AK23: 4 | AL23: 4 | AM23: 4
B24: =+B23 -> 1 | C24: =+C23+1 -> 4 | D24: 0 | E24: =B24&"."&C24&"."&D24 -> 1.4.0 | F24: Hörmann Door (West) | O24: =SUM(O25:O26) -> 24 | T24: =IF(S24<>"",IF($Z$9="x",WORKDAY(IF(WEEKDAY(R24,1)=7,R24+2,IF(WEEKDAY(R24,1)=1,R24+1,R24)),S24-1),R24+S24-1),"") | U24: =+SUMPRODUCT(U25:U26,O25:O26)/O24 -> 0.66666667 | V24: =+U24*O24 -> 16 | W24: =SUMIFS($AA24:$NZ24, $AA$8:$NZ$8, $W$13)/$O24 -> 0 | X24: =SUMIF($AA$9:$NZ$9, "<=" & $W$11,$AA24:$NZ24)/$O24 -> 0 | Y24: =+X24*O24 -> 0
B25: =+B24 -> 1 | C25: =+C24 -> 4 | D25: 1 | E25: =B25&"."&C25&"."&D25 -> 1.4.1 | F25: Steel structure | G25: 2 | H25: MYA | I25: B | J25: 1 | K25: 1 | L25: =+J25-K25 -> 0 | M25: 4 | N25: 4 | O25: =+N25*M25 -> 16 | P25: =+SUM(AA25:NZ25) -> 0 | Q25: =+O25-P25 -> 16 | T25: =IF(S25<>"",IF($Z$9="x",WORKDAY(IF(WEEKDAY(R25,1)=7,R25+2,IF(WEEKDAY(R25,1)=1,R25+1,R25)),S25-1),R25+S25-1),"") | U25: =+K25/J25 -> 1 | V25: =+U25*O25 -> 16 | W25: =SUMIFS($AA25:$NZ25, $AA$8:$NZ$8, $W$13)/$O25 -> 0 | X25: =SUMIF($AA$9:$NZ$9, "<=" & $W$11,$AA25:$NZ25)/$O25 -> 0 | Y25: =+X25*O25 -> 0
B26: =+B25 -> 1 | C26: =+C25 -> 4 | D26: 2 | E26: =B26&"."&C26&"."&D26 -> 1.4.2 | F26: Door | G26: 2 | H26: MYA | I26: B | J26: 1 | K26: 0 | L26: =+J26-K26 -> 1 | M26: 4 | N26: 2 | O26: =+N26*M26 -> 8 | P26: =+SUM(AA26:NZ26) -> 8 | Q26: =+O26-P26 -> 0 | R26: 46002 | S26: 2 | T26: =IF(S26<>"",IF($Z$9="x",WORKDAY(IF(WEEKDAY(R26,1)=7,R26+2,IF(WEEKDAY(R26,1)=1,R26+1,R26)),S26-1),R26+S26-1),"") -> 46003 | U26: =+K26/J26 -> 0 | V26: =+U26*O26 -> 0 | W26: =SUMIFS($AA26:$NZ26, $AA$8:$NZ$8, $W$13)/$O26 -> 0 | X26: =SUMIF($AA$9:$NZ$9, "<=" & $W$11,$AA26:$NZ26)/$O26 -> 1 | Y26: =+X26*O26 -> 8 | AR26: 4 | AS26: 4
B27: =+B26 -> 1 | C27: =+C26+1 -> 5 | D27: 0 | E27: =B27&"."&C27&"."&D27 -> 1.5.0 | F27: FT-07 Glass Rotation and Gasket replacement (East-West) | G27: 2,3,4 | H27: MYA | I27: A | J27: 7 | K27: 0 | L27: =+J27-K27 -> 7 | M27: 3 | N27: 6 | O27: =+N27*M27 -> 18 | P27: =+SUM(AA27:NZ27) -> 18 | Q27: =+O27-P27 -> 0 | R27: 46083 | S27: 5 | T27: =IF(S27<>"",IF($Z$9="x",WORKDAY(IF(WEEKDAY(R27,1)=7,R27+2,IF(WEEKDAY(R27,1)=1,R27+1,R27)),S27-1),R27+S27-1),"") -> 46087 | U27: =+K27/J27 -> 0 | V27: =+U27*O27 -> 0 | W27: =SUMIFS($AA27:$NZ27, $AA$8:$NZ$8, $W$13)/$O27 -> 0 | X27: =SUMIF($AA$9:$NZ$9, "<=" & $W$11,$AA27:$NZ27)/$O27 -> 0 | Y27: =+X27*O27 -> 0 | DU27: 3 | DV27: 3 | DW27: 3 | DX27: 3 | DY27: 3 | DZ27: 3
B28: =+B27 -> 1 | C28: =+C27+1 -> 6 | D28: 0 | E28: =B28&"."&C28&"."&D28 -> 1.6.0 | F28: Breuninger facade –Bottom Al. Finishing Reinforcement | G28: 2 | H28: MYA | I28: A | J28: 30 | K28: 30 | L28: =+J28-K28 -> 0 | M28: 2 | N28: 6 | O28: =+N28*M28 -> 12 | P28: =+SUM(AA28:NZ28) -> 12 | Q28: =+O28-P28 -> 0 | R28: 45992 | S28: 5 | T28: =IF(S28<>"",IF($Z$9="x",WORKDAY(IF(WEEKDAY(R28,1)=7,R28+2,IF(WEEKDAY(R28,1)=1,R28+1,R28)),S28-1),R28+S28-1),"") -> 45996 | U28: =+K28/J28 -> 1 | V28: =+U28*O28 -> 12 | W28: =SUMIFS($AA28:$NZ28, $AA$8:$NZ$8, $W$13)/$O28 -> 0 | X28: =SUMIF($AA$9:$NZ$9, "<=" & $W$11,$AA28:$NZ28)/$O28 -> 1 | Y28: =+X28*O28 -> 12 | AH28: 2 | AI28: 2 | AJ28: 2 | AK28: 2 | AL28: 2 | AM28: 2
B29: =+B28 -> 1 | C29: =+C28+1 -> 7 | D29: 0 | E29: =B29&"."&C29&"."&D29 -> 1.7.0 | F29: RT02 Additional Balustrade Module (NTA) | G29: 2 | H29: MYA | I29: C | J29: 2 | K29: 0 | L29: =+J29-K29 -> 2 | M29: 4 | N29: 3 | O29: =+N29*M29 -> 12 | P29: =+SUM(AA29:NZ29) -> 12 | Q29: =+O29-P29 -> 0 | R29: 46083 | S29: 3 | T29: =IF(S29<>"",IF($Z$9="x",WORKDAY(IF(WEEKDAY(R29,1)=7,R29+2,IF(WEEKDAY(R29,1)=1,R29+1,R29)),S29-1),R29+S29-1),"") -> 46085 | U29: =+K29/J29 -> 0 | V29: =+U29*O29 -> 0 | W29: =SUMIFS($AA29:$NZ29, $AA$8:$NZ$8, $W$13)/$O29 -> 0 | X29: =SUMIF($AA$9:$NZ$9, "<=" & $W$11,$AA29:$NZ29)/$O29 -> 0 | Y29: =+X29*O29 -> 0 | DU29: 4 | DV29: 4 | DW29: 4
B30: =+B29 -> 1 | C30: =+C29+1 -> 8 | D30: 0 | E30: =B30&"."&C30&"."&D30 -> 1.8.0 | F30: FT-13 Canopy – Anodized Al. Sheet Replacement + Cap Replacement | G30: 2.3 | H30: MYA | I30: B | J30: 60 | K30: 0 | L30: =+J30-K30 -> 60 | M30: 4 | N30: 6 | O30: =+N30*M30 -> 24 | P30: =+SUM(AA30:NZ30) -> 24 | Q30: =+O30-P30 -> 0 | R30: 46111 | S30: 5 | T30: =IF(S30<>"",IF($Z$9="x",WORKDAY(IF(WEEKDAY(R30,1)=7,R30+2,IF(WEEKDAY(R30,1)=1,R30+1,R30)),S30-1),R30+S30-1),"") -> 46115 | U30: =+K30/J30 -> 0 | V30: =+U30*O30 -> 0 | W30: =SUMIFS($AA30:$NZ30, $AA$8:$NZ$8, $W$13)/$O30 -> 0 | X30: =SUMIF($AA$9:$NZ$9, "<=" & $W$11,$AA30:$NZ30)/$O30 -> 0 | Y30: =+X30*O30 -> 0 | EW30: 4 | EX30: 4 | EY30: 4 | EZ30: 4 | FA30: 4 | FB30: 4
